Workbook

Sheet ILTA
A1: MASSA | F1: KAUPPA | K1: PAKASTE | P1: KÄYTTÖTAVARA | T1: 47
A2: Kerättävä määrä | B2: =Q12 -> 5572 | F2: Kerättävä määrä | G2: =Q13 -> 986 | K2: Kerättävä määrä | L2: =Q14 -> 802 | P2: Kerättävä määrä | Q2: =Q17 -> 104
A3: Keräysteho kpl/h | B3: ='Keräysteho kplh'!B2 -> 178 | F3: Keräysteho kpl/h | G3: ='Keräysteho kplh'!B3 -> 73 | K3: Keräysteho kpl/h | L3: ='Keräysteho kplh'!B4 -> 108 | P3: Keräysteho kpl/h | Q3: ='Keräysteho kplh'!B7 -> 32
A4: Vuoron päättymisaika | B4: HKL | C4: Aikaa jäljellä (h) | D4: keräystunnit jäljellä | F4: Vuoron päättymisaika | G4: HKL | H4: Aikaa jäljellä (h) | I4: keräystunnit jäljellä | K4: Vuoron päättymisaika | L4: HKL | M4: Aikaa jäljellä (h) | N4: keräystunnit jäljellä | P4: Vuoron päättymisaika | R4: Aikaa jäljellä (h) | S4: keräystunnit jäljellä
A5: =TODAY()+TIME(11,0,0) -> 46315.458 | B5: 0 | C5: =A5-D13 -> 0.062923148 | D5: =B5*C5 -> 0 | F5: =TODAY()+TIME(11,0,0) -> 46315.458 | G5: 0 | H5: =F5-I13 -> 0.062923148 | I5: =G5*H5 -> 0 | K5: =TODAY()+TIME(11,0,0) -> 46315.458 | L5: 0 | M5: =K5-N13 -> 0.062923148 | N5: =L5*M5 -> 0 | P5: =S17 -> 46315.463 | Q5: 2 | R5: =P5-L25 -> 0.067708333 | S5: =R5*Q5 -> 0.13541667
A6: =TODAY()+TIME(12,0,0) -> 46315.5 | B6: 3 | C6: =A6-D13 -> 0.10458981 | D6: =B6*C6 -> 0.31376944 | F6: =TODAY()+TIME(12,0,0) -> 46315.5 | G6: 9 | H6: =F6-I13 -> 0.10458981 | I6: =G6*H6 -> 0.94130833 | K6: =TODAY()+TIME(12,0,0) -> 46315.5 | L6: 1 | M6: =K6-N13 -> 0.10458981 | N6: =L6*M6 -> 0.10458981 | P6: Kokonaistyötunnit (Jäljellä) | Q6: =S5 -> 0.13541667 | R6: Kerääjät / yht | S6: =Q5 -> 2
A7: =TODAY()+TIME(13,0,0) -> 46315.542 | B7: 4 | C7: =A7-D13 -> 0.14625648 | D7: =B7*C7 -> 0.58502593 | F7: =TODAY()+TIME(13,0,0) -> 46315.542 | G7: 1 | H7: =F7-I13 -> 0.14625648 | I7: =G7*H7 -> 0.14625648 | K7: =TODAY()+TIME(13,0,0) -> 46315.542 | L7: 2 | M7: =K7-N13 -> 0.14625648 | N7: =L7*M7 -> 0.29251296 | P7: Tuotteita / kerääjä | Q7: =Q2/(Q5) -> 52
A8: =TODAY()+TIME(14,0,0) -> 46315.583 | B8: 2 | C8: =A8-D13 -> 0.18792315 | D8: =B8*C8 -> 0.3758463 | F8: =TODAY()+TIME(14,0,0) -> 46315.583 | G8: 1 | H8: =F8-I13 -> 0.18792315 | I8: =G8*H8 -> 0.18792315 | K8: =TODAY()+TIME(14,0,0) -> 46315.583 | L8: 0 | M8: =K8-N13 -> 0.18792315 | N8: =L8*M8 -> 0 | P8: Arvioitu kesto (Tunnit) | Q8: =Q2/(Q3*(Q5))/24 -> 0.067708333
A9: =TODAY()+TIME(15,0,0) -> 46315.625 | B9: 0 | C9: =A9-D13 -> 0.22958981 | D9: =B9*C9 -> 0 | F9: =TODAY()+TIME(15,0,0) -> 46315.625 | G9: 0 | H9: =F9-I13 -> 0.22958981 | I9: =G9*H9 -> 0 | K9: =TODAY()+TIME(15,0,0) -> 46315.625 | L9: 0 | M9: =K9-N13 -> 0.22958981 | N9: =L9*M9 -> 0 | P9: Arvioitu valmistuminen | Q9: =IFERROR(L25+Q8+IF(Q2>=400,TIME(0,24,0),0),"") -> 46315.463
A10: Kokonaistyötunnit (Jäljellä) | B10: =D5+D6+D7+D8+D9 -> 1.2746417 | C10: Kerääjät / yht | D10: =B9+B8+B7+B6+B5 -> 9 | F10: Kokonaistyötunnit (Jäljellä) | G10: =I5+I6+I7+I8+I9 -> 1.275488 | H10: Kerääjät / yht | I10: =G9+G8+G7+G6+G5 -> 11 | K10: Kokonaistyötunnit (Jäljellä) | L10: =N9+N8+N7+N6+N5 -> 0.39710278 | M10: Kerääjät / yht | N10: =L9+L8+L7+L6+L5 -> 3
A11: Tuotteita / kerääjä | B11: =B2/(B6+B7+B8+B9) -> 619.11111 | F11: Tuotteita / kerääjä | G11: =G2/(G6+G7+G8+G9) -> 89.636364 | K11: Tuotteita / kerääjä | L11: =L2/(L6+L7+L8+L9) -> 267.33333 | P11: KERÄTTÄVÄ MÄÄRÄ | R11: ARVIOITU VALMISTUMINEN
A12: Arvioitu kesto (Tunnit) | B12: =B2/(B3*(B6+B7+B8+B9+B5))/24 -> 0.14492301 | F12: Arvioitu kesto (Tunnit) | G12: =G2/(G3*(G6+G7+G8+G9+G5))/24 -> 0.051162308 | K12: Arvioitu kesto (Tunnit) | L12: =L2/(L3*(L6+L7+L8+L9+L5))/24 -> 0.10313786 | P12: MASSA | Q12: 5572 | R12: MASSA | S12: =B13 -> 46315.557
A13: Arvioitu valmistuminen | B13: =IFERROR(D13+B12+IF(B2>=3000,TIME(0,24,0),0),"") -> 46315.557 | C13: Nykyinen aika | D13: =NOW() -> 46315.395 | F13: Arvioitu valmistuminen | G13: =IFERROR(I13+G12+IF(G2>=1500,TIME(0,24,0),0),"") -> 46315.447 | H13: Nykyinen aika | I13: =NOW() -> 46315.395 | K13: Arvioitu valmistuminen | L13: =IFERROR(N13+L12+IF(L2>=400,TIME(0,24,0),0),"") -> 46315.515 | M13: Nykyinen aika | N13: =NOW() -> 46315.395 | P13: KAUPPA | Q13: 986 | R13: KAUPPA | S13: =G13 -> 46315.447
P14: PAKASTE | Q14: 802 | R14: PAKASTE | S14: =L13 -> 46315.515
A15: LÄMMIN AUTO | F15: KYLMÄ AUTO | K15: Lisätyötarve HH:MM | L15: =N29-N28-(L17/24) -> -1.8678226 | M15: Lisätyötuntikapa | N15: =N16+(L16*L17) -> 17150.539 | P15: LÄMMIN AUTO | Q15: 254 | R15: LÄMMIN AUTO | S15: =B27 -> 46315.403 | AB15: =IFERROR(((N17-N16)/L16)/24,0)+IF(AA26<0,-AA26,0) -> -1.8678226
A16: Kerättävä määrä | B16: =Q15 -> 254 | F16: Kerättävä määrä | G16: =Q16 -> 1021 | K16: Keräysteho kpl/h ET | L16: =(B3*B10+G3*G10+L3*L10+B17*B24+G17*G24)/ (B10+G10+L10+B24+G24) -> 189.96136 | M16: Keräyskapa | N16: =L16*N28*24 -> 17150.539 | P16: KYLMÄ AUTO | Q16: 1021 | R16: KYLMÄ AUTO | S16: =G27 -> 46315.448
A17: Keräysteho kpl/h | B17: ='Keräysteho kplh'!B5 -> 449 | F17: Keräysteho kpl/h | G17: ='Keräysteho kplh'!B6 -> 401 | K17: Lisätunnit | L17: 0 | M17: Kerättävä määrä ET | N17: =B2+G2+L2+B16+G16 -> 8635 | P17: KÄYTTÖTAVARA | Q17: 104 | R17: KÄYTTÖTAVARA | S17: =Q9 -> 46315.463
A18: Vuoron päättymisaika | B18: HKL | C18: Aikaa jäljellä (h) | D18: keräystunnit jäljellä | F18: Vuoron päättymisaika | G18: HKL | H18: Aikaa jäljellä (h) | I18: keräystunnit jäljellä | K18: Kahvitauot HH:MM | L18: =L26*24/1440 -> 0.46666667 | M18: Kerättävä määrä ET + KT | N18: =B2+G2+L2+Q2+B16+G16 -> 8739 | P18: KOKONAIS | Q18: =Q12+Q13+Q14+Q15+Q16+Q17 -> 8739 | R18: KOKONAIS | S18: =L28 -> 46315.557
A19: =TODAY()+TIME(11,0,0) -> 46315.458 | B19: 0 | C19: =A19-D27 -> 0.062923148 | D19: =B19*C19 -> 0 | F19: =TODAY()+TIME(11,0,0) -> 46315.458 | G19: 0 | H19: =F19-I27 -> 0.062923148 | I19: =G19*H19 -> 0 | K19: Vuoron päättymisaika | L19: HKL ET | M19: Keräysteho kpl/h ET + KT | N19: =(B3*B10+G3*G10+L3*L10+Q3*Q6+B17*B24+G17*G24)/ (B10+G10+L10+Q6+B24+G24) -> 184.47274
A20: =TODAY()+TIME(12,0,0) -> 46315.5 | B20: 0 | C20: =A20-D27 -> 0.10458981 | D20: =B20*C20 -> 0 | F20: =TODAY()+TIME(12,0,0) -> 46315.5 | G20: 0 | H20: =F20-I27 -> 0.10458981 | I20: =G20*H20 -> 0 | K20: =TODAY()+TIME(11,0,0) -> 46315.458 | L20: =G19+B19+B5+G5+L5 -> 0 | M20: =K20-L25 -> 0.062923148 | N20: =L20*M20 -> 0 | P20: LAATIKOITA JÄLJELLÄ | R20: KIERROKSIA JÄLJELLÄ
A21: =TODAY()+TIME(13,0,0) -> 46315.542 | B21: 1 | C21: =A21-D27 -> 0.14625648 | D21: =B21*C21 -> 0.14625648 | F21: =TODAY()+TIME(13,0,0) -> 46315.542 | G21: 2 | H21: =F21-I27 -> 0.14625648 | I21: =G21*H21 -> 0.29251296 | K21: =TODAY()+TIME(12,0,0) -> 46315.5 | L21: =G20+B20+B6+G6+L6 -> 13 | M21: =K21-L25 -> 0.10458981 | N21: =L21*M21 -> 1.3596676 | P21: XL MASSA | Q21: 0 | R21: KIERROKSIA | S21: =Q21/25 -> 0
A22: =TODAY()+TIME(14,0,0) -> 46315.583 | B22: 2 | C22: =A22-D27 -> 0.18792315 | D22: =B22*C22 -> 0.3758463 | F22: =TODAY()+TIME(14,0,0) -> 46315.583 | G22: 0 | H22: =F22-I27 -> 0.18792315 | I22: =G22*H22 -> 0 | K22: =TODAY()+TIME(13,0,0) -> 46315.542 | L22: =G21+B21+B7+G7+L7 -> 10 | M22: =K22-L25 -> 0.14625648 | N22: =L22*M22 -> 1.4625648 | P22: MASSA | Q22: 0 | R22: KIERROKSIA | S22: =B32 -> 0
A23: =TODAY()+TIME(15,0,0) -> 46315.625 | B23: 0 | C23: =A23-D27 -> 0.22958981 | D23: =B23*C23 -> 0 | F23: =TODAY()+TIME(15,0,0) -> 46315.625 | G23: 0 | H23: =F23-I27 -> 0.22958981 | I23: =G23*H23 -> 0 | K23: =TODAY()+TIME(14,0,0) -> 46315.583 | L23: =G22+B22+B8+G8+L8 -> 5 | M23: =K23-L25 -> 0.18792315 | N23: =L23*M23 -> 0.93961574 | P23: KAUPPA | Q23: 0 | R23: KIERROKSIA | S23: =G32 -> 0
A24: Kokonaistyötunnit (Jäljellä) | B24: =D23+D22+D21+D20+D19 -> 0.52210278 | C24: Kerääjät / yht | D24: =B23+B22+B21+B20+B19 -> 3 | F24: Kokonaistyötunnit (Jäljellä) | G24: =I23+I22+I21+I20+I19 -> 0.29251296 | H24: Kerääjät / yht | I24: =G23+G22+G21+G20+G19 -> 2 | K24: =TODAY()+TIME(15,0,0) -> 46315.625 | L24: =G23+B23+B9+G9+L9 -> 0 | M24: =K24-L25 -> 0.22958981 | N24: =L24*M24 -> 0 | P24: PAKASTE | Q24: 0 | R24: PSS | S24: -
A25: Tuotteita / kerääjä | B25: =B16/(B20+B21+B22+B23) -> 84.666667 | F25: Tuotteita / kerääjä | G25: =G16/(G20+G21+G22+G23) -> 510.5 | K25: Nykyinen aika | L25: =NOW() -> 46315.395 | M25: Ylim. Työaika | N25: =IF(AA25<0,"-","")&INT(ROUND(ABS(AA25)*1440,0)/60)&":"&TEXT(MOD(ROUND(ABS(AA25)*1440,0),60),"00") -> 34:56 | P25: LÄMMIN AUTO | Q25: 0 | R25: RULLAKOITA | S25: =B38 -> 0 | AA25: =N28-IFERROR((B2/B3+G2/G3+L2/L3+B16/B17+G16/G17)/24,0)+L17/24 -> 1.4556822
A26: Arvioitu kesto (Tunnit) | B26: =B16/(B17*(B20+B21+B22+B23+B19))/24 -> 0.0078569661 | F26: Arvioitu kesto (Tunnit) | G26: =G16/(G17*(G20+G21+G22+G23+G19))/24 -> 0.053044472 | K26: Kerääjät / yht | L26: =L24+L23+L22+L21+L20 -> 28 | M26: Ylim. Työaika - tauko | N26: =IF(AA26<0,"-","")&INT(ROUND(ABS(AA26)*1440,0)/60)&":"&TEXT(MOD(ROUND(ABS(AA26)*1440,0),60),"00") -> 23:44 | P26: KYLMÄ AUTO | Q26: 0 | R26: RULLAKOITA | S26: =D38 -> 0 | AA26: =AA25-L18 -> 0.98901555
A27: Arvioitu valmistuminen | B27: =IFERROR(D27+B26+IF(B16>=5000,TIME(0,24,0),0),"") -> 46315.403 | C27: Nykyinen aika | D27: =NOW() -> 46315.395 | F27: Arvioitu valmistuminen | G27: =IFERROR(I27+G26+IF(G16>=5000,TIME(0,24,0),0),"") -> 46315.448 | H27: Nykyinen aika | I27: =NOW() -> 46315.395 | K27: Tuotteita / kerääjä | L27: =N17/(L21+L22+L23+L24) -> 308.39286 | M27: Ylim. Työaika - keskiarvo | N27: =ABS(AA26+AA25)/2 -> 1.2223489 | P27: KÄYTTÖTAVARA | Q27: 0 | R27: KIERROKSIA | S27: =L39 -> 0
K28: Arvioitu valmistuminen | L28: =MAX(IFERROR(B27*1,0),IFERROR(G27*1,0),IFERROR(L13*1,0),IFERROR(G13*1,0),IFERROR(B13*1,0),IFERROR(Q9*1,0)) -> 46315.557 | M28: Kokonaistyötunnit (Jäljellä) | N28: =N21+N22+N23+N24+N20 -> 3.7618481 | P28: KOKONAIS | Q28: =B31+D31+L34+L38+D37+B37 -> 0 | R28: KOKONAIS | S28: =S27+S26+S25+S23+S22+S21 -> 0
A29: MASSA | F29: KAUPPA | K29: Arvioitu valm. + tauko | L29: =L28+(L18/24) -> 46315.576 | M29: Tarvittavat työtunnit | N29: =N17/L16/24 -> 1.8940256 | P29: ~ Per kerääjä | Q29: =Q28/L26 -> 0 | R29: ~ Per kerääjä | S29: =S28/L26 -> 0
A30: Tuotteita | B30: =B2 -> 5572 | C30: Kerääjät / yht | D30: =D10 -> 9 | F30: Tuotteita | G30: =G2 -> 986 | H30: Kerääjät / yht | I30: =I10 -> 11 | K30: Arvioitu valm. keskiarvo | L30: =AVERAGE(L28,L29) -> 46315.567 | M30: Arvioitu kesto HH:MM | N30: =MAX(IFERROR(B26*1,0),IFERROR(G26*1,0),IFERROR(L12*1,0),IFERROR(G12*1,0),IFERROR(B12*1,0),IFERROR(Q8*1,0)) -> 0.14492301
A31: Laatikoita | B31: =Q22 -> 0 | F31: Laatikoita | G31: =Q23 -> 0 | P31: RULLAKOITA / LAATIKOITA | R31: PER KERÄÄJÄ
A32: Kierroksia | B32: =B31/9 -> 0 | F32: Kierroksia | G32: =G31/9 -> 0 | K32: PAKASTE | P32: MASSA | R32: KIERROKSIA | S32: =S22/D10 -> 0
A33: Kierroksia/kerääjä | B33: =B32/D10 -> 0 | F33: Kierroksia/kerääjä | G33: =G32/I10 -> 0 | K33: Tuotteita | L33: =L2 -> 802 | M33: Kerääjät / yht | N33: =N10 -> 3 | P33: KAUPPA | R33: KIERROKSIA | S33: =S23/I10 -> 0
K34: Pss/laatikoita | L34: =Q24 -> 0 | M34: ~ Per kerääjä | N34: =L34/N10 -> 0 | P34: PAKASTE | R34: ~ PER KERÄÄJÄ | S34: =N34 -> 0
A35: LÄMMIN AUTO | P35: LÄMMIN AUTO | R35: RULLAKOITA | S35: =S25/D24 -> 0
A36: Tuotteita | B36: =B16 -> 254 | C36: Kerääjät / yht | D36: =D16 -> 0 | F36: Tuotteita | G36: =G16 -> 1021 | H36: Kerääjät / yht | I36: =I16 -> 0 | K36: KÄYTTÖTAVARA | P36: KYLMÄ AUTO | R36: RULLAKOITA | S36: =S26/I24 -> 0
A37: Laatikoita | B37: =Q25 -> 0 | F37: Laatikoita | G37: =Q26 -> 0 | K37: Tuotteita | L37: =Q2 -> 104 | M37: Kerääjät / yht | N37: =S6 -> 2 | P37: KÄYTTÖTAVARA | R37: KIERROKSIA | S37: =S27/S6 -> 0
A38: Rullakoita | B38: =B37/10 -> 0 | F38: Rullakoita | G38: =G37/10 -> 0 | K38: Laatikoita | L38: =Q27 -> 0 | P38: =NOW() -> 46315.395 | Q38: ↻ | R38: =I27 -> 46315.395
A39: Rullakoita/kerääjä | B39: =B38/D24 -> 0 | F39: Rullakoita/kerääjä | G39: =G38/I24 -> 0 | K39: Kierroksia | L39: =L38/16 -> 0 | M39: Kierroksia/kerääjä | N39: =L39/N37 -> 0
P47: Nykyinen aika
...

Sheet AAMU
A1: MASSA | F1: KAUPPA | K1: PAKASTE | P1: KÄYTTÖTAVARA | T1: 47
A2: Kerättävä määrä | B2: =Q12 -> 0 | F2: Kerättävä määrä | G2: =Q13 -> 0 | K2: Kerättävä määrä | L2: =Q14 -> 0 | P2: Kerättävä määrä | Q2: =Q17 -> 0
A3: Keräysteho kpl/h | B3: ='Keräysteho kplh'!B2 -> 178 | F3: Keräysteho kpl/h | G3: ='Keräysteho kplh'!B3 -> 73 | K3: Keräysteho kpl/h | L3: ='Keräysteho kplh'!B4 -> 108 | P3: Keräysteho kpl/h | Q3: ='Keräysteho kplh'!B7 -> 32
A4: Vuoron päättymisaika | B4: HKL | C4: Aikaa jäljellä (h) | D4: keräystunnit jäljellä | F4: Vuoron päättymisaika | G4: HKL | H4: Aikaa jäljellä (h) | I4: keräystunnit jäljellä | K4: Vuoron päättymisaika | L4: HKL | M4: Aikaa jäljellä (h) | N4: keräystunnit jäljellä | P4: Vuoron päättymisaika | R4: Aikaa jäljellä (h) | S4: keräystunnit jäljellä
A5: =TODAY()+TIME(11,0,0) -> 46315.458 | B5: 0 | C5: =A5-D13 -> 0.062923148 | D5: =B5*C5 -> 0 | F5: =TODAY()+TIME(11,0,0) -> 46315.458 | G5: 0 | H5: =F5-I13 -> 0.062923148 | I5: =G5*H5 -> 0 | K5: =TODAY()+TIME(11,0,0) -> 46315.458 | L5: 0 | M5: =K5-N13 -> 0.062923148 | N5: =L5*M5 -> 0 | P5: =S17 | Q5: 0 | R5: =P5-L25 -> #VALUE! | S5: =R5*Q5 -> #VALUE!
A6: =TODAY()+TIME(12,0,0) -> 46315.5 | B6: 0 | C6: =A6-D13 -> 0.10458981 | D6: =B6*C6 -> 0 | F6: =TODAY()+TIME(12,0,0) -> 46315.5 | G6: 0 | H6: =F6-I13 -> 0.10458981 | I6: =G6*H6 -> 0 | K6: =TODAY()+TIME(12,0,0) -> 46315.5 | L6: 0 | M6: =K6-N13 -> 0.10458981 | N6: =L6*M6 -> 0 | P6: Kokonaistyötunnit (Jäljellä) | Q6: =S5 -> #VALUE! | R6: Kerääjät / yht | S6: =Q5 -> 0
A7: =TODAY()+TIME(13,0,0) -> 46315.542 | B7: 0 | C7: =A7-D13 -> 0.14625648 | D7: =B7*C7 -> 0 | F7: =TODAY()+TIME(13,0,0) -> 46315.542 | G7: 0 | H7: =F7-I13 -> 0.14625648 | I7: =G7*H7 -> 0 | K7: =TODAY()+TIME(13,0,0) -> 46315.542 | L7: 0 | M7: =K7-N13 -> 0.14625648 | N7: =L7*M7 -> 0 | P7: Tuotteita / kerääjä | Q7: =Q2/(Q5) -> #DIV/0!
A8: =TODAY()+TIME(14,0,0) -> 46315.583 | B8: 0 | C8: =A8-D13 -> 0.18792315 | D8: =B8*C8 -> 0 | F8: =TODAY()+TIME(14,0,0) -> 46315.583 | G8: 0 | H8: =F8-I13 -> 0.18792315 | I8: =G8*H8 -> 0 | K8: =TODAY()+TIME(14,0,0) -> 46315.583 | L8: 0 | M8: =K8-N13 -> 0.18792315 | N8: =L8*M8 -> 0 | P8: Arvioitu kesto (Tunnit) | Q8: =Q2/(Q3*(Q5))/24 -> #DIV/0!
A9: =TODAY()+TIME(15,0,0) -> 46315.625 | B9: 0 | C9: =A9-D13 -> 0.22958981 | D9: =B9*C9 -> 0 | F9: =TODAY()+TIME(15,0,0) -> 46315.625 | G9: 0 | H9: =F9-I13 -> 0.22958981 | I9: =G9*H9 -> 0 | K9: =TODAY()+TIME(15,0,0) -> 46315.625 | L9: 0 | M9: =K9-N13 -> 0.22958981 | N9: =L9*M9 -> 0 | P9: Arvioitu valmistuminen | Q9: =IFERROR(L25+Q8+IF(Q2>=400,TIME(0,24,0),0),"")
A10: Kokonaistyötunnit (Jäljellä) | B10: =D5+D6+D7+D8+D9 -> 0 | C10: Kerääjät / yht | D10: =B9+B8+B7+B6+B5 -> 0 | F10: Kokonaistyötunnit (Jäljellä) | G10: =I5+I6+I7+I8+I9 -> 0 | H10: Kerääjät / yht | I10: =G9+G8+G7+G6+G5 -> 0 | K10: Kokonaistyötunnit (Jäljellä) | L10: =N9+N8+N7+N6+N5 -> 0 | M10: Kerääjät / yht | N10: =L9+L8+L7+L6+L5 -> 0
A11: Tuotteita / kerääjä | B11: =B2/(B6+B7+B8+B9) -> #DIV/0! | F11: Tuotteita / kerääjä | G11: =G2/(G6+G7+G8+G9) -> #DIV/0! | K11: Tuotteita / kerääjä | L11: =L2/(L6+L7+L8+L9) -> #DIV/0! | P11: KERÄTTÄVÄ MÄÄRÄ | R11: ARVIOITU VALMISTUMINEN
A12: Arvioitu kesto (Tunnit) | B12: =B2/(B3*(B6+B7+B8+B9+B5))/24 -> #DIV/0! | F12: Arvioitu kesto (Tunnit) | G12: =G2/(G3*(G6+G7+G8+G9+G5))/24 -> #DIV/0! | K12: Arvioitu kesto (Tunnit) | L12: =L2/(L3*(L6+L7+L8+L9+L5))/24 -> #DIV/0! | P12: MASSA | Q12: 0 | R12: MASSA | S12: =B13
A13: Arvioitu valmistuminen | B13: =IFERROR(D13+B12+IF(B2>=3000,TIME(0,24,0),0),"") | C13: Nykyinen aika | D13: =NOW() -> 46315.395 | F13: Arvioitu valmistuminen | G13: =IFERROR(I13+G12+IF(G2>=1500,TIME(0,24,0),0),"") | H13: Nykyinen aika | I13: =NOW() -> 46315.395 | K13: Arvioitu valmistuminen | L13: =IFERROR(N13+L12+IF(L2>=400,TIME(0,24,0),0),"") | M13: Nykyinen aika | N13: =NOW() -> 46315.395 | P13: KAUPPA | Q13: 0 | R13: KAUPPA | S13: =G13
P14: PAKASTE | Q14: 0 | R14: PAKASTE | S14: =L13
A15: LÄMMIN AUTO | F15: KYLMÄ AUTO | K15: Lisätyötarve HH:MM | L15: =N29-N28-(L17/24) -> #DIV/0! | M15: Lisätyötuntikapa | N15: =N16+(L16*L17) -> #DIV/0! | P15: LÄMMIN AUTO | Q15: 0 | R15: LÄMMIN AUTO | S15: =B27 | AB15: =IFERROR(((N17-N16)/L16)/24,0)+IF(AA26<0,-AA26,0) -> 0
A16: Kerättävä määrä | B16: =Q15 -> 0 | F16: Kerättävä määrä | G16: =Q16 -> 0 | K16: Keräysteho kpl/h ET | L16: =(B3*B10+G3*G10+L3*L10+B17*B24+G17*G24)/ (B10+G10+L10+B24+G24) -> #DIV/0! | M16: Keräyskapa | N16: =L16*N28*24 -> #DIV/0! | P16: KYLMÄ AUTO | Q16: 0 | R16: KYLMÄ AUTO | S16: =G27
A17: Keräysteho kpl/h | B17: ='Keräysteho kplh'!B5 -> 449 | F17: Keräysteho kpl/h | G17: ='Keräysteho kplh'!B6 -> 401 | K17: Lisätunnit | L17: 0 | M17: Kerättävä määrä ET | N17: =B2+G2+L2+B16+G16 -> 0 | P17: KÄYTTÖTAVARA | Q17: 0 | R17: KÄYTTÖTAVARA | S17: =Q9
A18: Vuoron päättymisaika | B18: HKL | C18: Aikaa jäljellä (h) | D18: keräystunnit jäljellä | F18: Vuoron päättymisaika | G18: HKL | H18: Aikaa jäljellä (h) | I18: keräystunnit jäljellä | K18: Kahvitauot HH:MM | L18: =L26*24/1440 -> 0 | M18: Kerättävä määrä ET + KT | N18: =B2+G2+L2+Q2+B16+G16 -> 0 | P18: KOKONAIS | Q18: =Q12+Q13+Q14+Q15+Q16+Q17 -> 0 | R18: KOKONAIS | S18: =L28 -> 0
A19: =TODAY()+TIME(11,0,0) -> 46315.458 | B19: 0 | C19: =A19-D27 -> 0.062923148 | D19: =B19*C19 -> 0 | F19: =TODAY()+TIME(11,0,0) -> 46315.458 | G19: 0 | H19: =F19-I27 -> 0.062923148 | I19: =G19*H19 -> 0 | K19: Vuoron päättymisaika | L19: HKL ET | M19: Keräysteho kpl/h ET + KT | N19: =(B3*B10+G3*G10+L3*L10+Q3*Q6+B17*B24+G17*G24)/ (B10+G10+L10+Q6+B24+G24) -> #VALUE!
A20: =TODAY()+TIME(12,0,0) -> 46315.5 | B20: 0 | C20: =A20-D27 -> 0.10458981 | D20: =B20*C20 -> 0 | F20: =TODAY()+TIME(12,0,0) -> 46315.5 | G20: 0 | H20: =F20-I27 -> 0.10458981 | I20: =G20*H20 -> 0 | K20: =TODAY()+TIME(11,0,0) -> 46315.458 | L20: =G19+B19+B5+G5+L5 -> 0 | M20: =K20-L25 -> 0.062923148 | N20: =L20*M20 -> 0 | P20: LAATIKOITA JÄLJELLÄ | R20: KIERROKSIA JÄLJELLÄ
A21: =TODAY()+TIME(13,0,0) -> 46315.542 | B21: 0 | C21: =A21-D27 -> 0.14625648 | D21: =B21*C21 -> 0 | F21: =TODAY()+TIME(13,0,0) -> 46315.542 | G21: 0 | H21: =F21-I27 -> 0.14625648 | I21: =G21*H21 -> 0 | K21: =TODAY()+TIME(12,0,0) -> 46315.5 | L21: =G20+B20+B6+G6+L6 -> 0 | M21: =K21-L25 -> 0.10458981 | N21: =L21*M21 -> 0 | P21: XL MASSA | Q21: 0 | R21: KIERROKSIA | S21: =Q21/25 -> 0
A22: =TODAY()+TIME(14,0,0) -> 46315.583 | B22: 0 | C22: =A22-D27 -> 0.18792315 | D22: =B22*C22 -> 0 | F22: =TODAY()+TIME(14,0,0) -> 46315.583 | G22: 0 | H22: =F22-I27 -> 0.18792315 | I22: =G22*H22 -> 0 | K22: =TODAY()+TIME(13,0,0) -> 46315.542 | L22: =G21+B21+B7+G7+L7 -> 0 | M22: =K22-L25 -> 0.14625648 | N22: =L22*M22 -> 0 | P22: MASSA | Q22: 0 | R22: KIERROKSIA | S22: =B32 -> 0
A23: =TODAY()+TIME(15,0,0) -> 46315.625 | B23: 0 | C23: =A23-D27 -> 0.22958981 | D23: =B23*C23 -> 0 | F23: =TODAY()+TIME(15,0,0) -> 46315.625 | G23: 0 | H23: =F23-I27 -> 0.22958981 | I23: =G23*H23 -> 0 | K23: =TODAY()+TIME(14,0,0) -> 46315.583 | L23: =G22+B22+B8+G8+L8 -> 0 | M23: =K23-L25 -> 0.18792315 | N23: =L23*M23 -> 0 | P23: KAUPPA | Q23: 0 | R23: KIERROKSIA | S23: =G32 -> 0
A24: Kokonaistyötunnit (Jäljellä) | B24: =D23+D22+D21+D20+D19 -> 0 | C24: Kerääjät / yht | D24: =B23+B22+B21+B20+B19 -> 0 | F24: Kokonaistyötunnit (Jäljellä) | G24: =I23+I22+I21+I20+I19 -> 0 | H24: Kerääjät / yht | I24: =G23+G22+G21+G20+G19 -> 0 | K24: =TODAY()+TIME(15,0,0) -> 46315.625 | L24: =G23+B23+B9+G9+L9 -> 0 | M24: =K24-L25 -> 0.22958981 | N24: =L24*M24 -> 0 | P24: PAKASTE | Q24: 0 | R24: PSS | S24: -
A25: Tuotteita / kerääjä | B25: =B16/(B20+B21+B22+B23) -> #DIV/0! | F25: Tuotteita / kerääjä | G25: =G16/(G20+G21+G22+G23) -> #DIV/0! | K25: Nykyinen aika | L25: =NOW() -> 46315.395 | M25: Ylim. Työaika | N25: =IF(AA25<0,"-","")&INT(ROUND(ABS(AA25)*1440,0)/60)&":"&TEXT(MOD(ROUND(ABS(AA25)*1440,0),60),"00") -> 0:00 | P25: LÄMMIN AUTO | Q25: 0 | R25: RULLAKOITA | S25: =B38 -> 0 | AA25: =N28-IFERROR((B2/B3+G2/G3+L2/L3+B16/B17+G16/G17)/24,0)+L17/24 -> 0
A26: Arvioitu kesto (Tunnit) | B26: =B16/(B17*(B20+B21+B22+B23+B19))/24 -> #DIV/0! | F26: Arvioitu kesto (Tunnit) | G26: =G16/(G17*(G20+G21+G22+G23+G19))/24 -> #DIV/0! | K26: Kerääjät / yht | L26: =L24+L23+L22+L21+L20 -> 0 | M26: Ylim. Työaika - tauko | N26: =IF(AA26<0,"-","")&INT(ROUND(ABS(AA26)*1440,0)/60)&":"&TEXT(MOD(ROUND(ABS(AA26)*1440,0),60),"00") -> 0:00 | P26: KYLMÄ AUTO | Q26: 0 | R26: RULLAKOITA | S26: =D38 -> 0 | AA26: =AA25-L18 -> 0
A27: Arvioitu valmistuminen | B27: =IFERROR(D27+B26+IF(B16>=5000,TIME(0,24,0),0),"") | C27: Nykyinen aika | D27: =NOW() -> 46315.395 | F27: Arvioitu valmistuminen | G27: =IFERROR(I27+G26+IF(G16>=5000,TIME(0,24,0),0),"") | H27: Nykyinen aika | I27: =NOW() -> 46315.395 | K27: Tuotteita / kerääjä | L27: =N17/(L21+L22+L23+L24) -> #DIV/0! | M27: Ylim. Työaika - keskiarvo | N27: =ABS(AA26+AA25)/2 -> 0 | P27: KÄYTTÖTAVARA | Q27: 0 | R27: KIERROKSIA | S27: =L39 -> 0
K28: Arvioitu valmistuminen | L28: =MAX(IFERROR(B27*1,0),IFERROR(G27*1,0),IFERROR(L13*1,0),IFERROR(G13*1,0),IFERROR(B13*1,0),IFERROR(Q9*1,0)) -> 0 | M28: Kokonaistyötunnit (Jäljellä) | N28: =N21+N22+N23+N24+N20 -> 0 | P28: KOKONAIS | Q28: =B31+D31+L34+L38+D37+B37 -> 0 | R28: KOKONAIS | S28: =S27+S26+S25+S23+S22+S21 -> 0
A29: MASSA | F29: KAUPPA | K29: Arvioitu valm. + tauko | L29: =L28+(L18/24) -> 0 | M29: Tarvittavat työtunnit | N29: =N17/L16/24 -> #DIV/0! | P29: ~ Per kerääjä | Q29: =Q28/L26 -> #DIV/0! | R29: ~ Per kerääjä | S29: =S28/L26 -> #DIV/0!
A30: Tuotteita | B30: =B2 -> 0 | C30: Kerääjät / yht | D30: =D10 -> 0 | F30: Tuotteita | G30: =G2 -> 0 | H30: Kerääjät / yht | I30: =I10 -> 0 | K30: Arvioitu valm. keskiarvo | L30: =AVERAGE(L28,L29) -> 0 | M30: Arvioitu kesto HH:MM | N30: =MAX(IFERROR(B26*1,0),IFERROR(G26*1,0),IFERROR(L12*1,0),IFERROR(G12*1,0),IFERROR(B12*1,0),IFERROR(Q8*1,0)) -> 0
A31: Laatikoita | B31: =Q22 -> 0 | F31: Laatikoita | G31: =Q23 -> 0 | P31: RULLAKOITA / LAATIKOITA | R31: PER KERÄÄJÄ
A32: Kierroksia | B32: =B31/9 -> 0 | F32: Kierroksia | G32: =G31/9 -> 0 | K32: PAKASTE | P32: MASSA | R32: KIERROKSIA | S32: =S22/D10 -> #DIV/0!
A33: Kierroksia/kerääjä | B33: =B32/D10 -> #DIV/0! | F33: Kierroksia/kerääjä | G33: =G32/I10 -> #DIV/0! | K33: Tuotteita | L33: =L2 -> 0 | M33: Kerääjät / yht | N33: =N10 -> 0 | P33: KAUPPA | R33: KIERROKSIA | S33: =S23/I10 -> #DIV/0!
K34: Pss/laatikoita | L34: =Q24 -> 0 | M34: ~ Per kerääjä | N34: =L34/N10 -> #DIV/0! | P34: PAKASTE | R34: ~ PER KERÄÄJÄ | S34: =N34 -> #DIV/0!
A35: LÄMMIN AUTO | P35: LÄMMIN AUTO | R35: RULLAKOITA | S35: =S25/D24 -> #DIV/0!
A36: Tuotteita | B36: =B16 -> 0 | C36: Kerääjät / yht | D36: =D16 -> 0 | F36: Tuotteita | G36: =G16 -> 0 | H36: Kerääjät / yht | I36: =I16 -> 0 | K36: KÄYTTÖTAVARA | P36: KYLMÄ AUTO | R36: RULLAKOITA | S36: =S26/I24 -> #DIV/0!
A37: Laatikoita | B37: =Q25 -> 0 | F37: Laatikoita | G37: =Q26 -> 0 | K37: Tuotteita | L37: =Q2 -> 0 | M37: Kerääjät / yht | N37: =S6 -> 0 | P37: KÄYTTÖTAVARA | R37: KIERROKSIA | S37: =S27/S6 -> #DIV/0!
A38: Rullakoita | B38: =B37/10 -> 0 | F38: Rullakoita | G38: =G37/10 -> 0 | K38: Laatikoita | L38: =Q27 -> 0 | P38: =NOW() -> 46315.395 | Q38: ↻ | R38: =I27 -> 46315.395
A39: Rullakoita/kerääjä | B39: =B38/D24 -> #DIV/0! | F39: Rullakoita/kerääjä | G39: =G38/I24 -> #DIV/0! | K39: Kierroksia | L39: =L38/16 -> 0 | M39: Kierroksia/kerääjä | N39: =L39/N37 -> #DIV/0!
P47: Nykyinen aika
...

Sheet Alkuperäinen
A1: MASSA | F1: KAUPPA | K1: PAKASTE | P1: KÄYTTÖTAVARA
A2: Kerättävä määrä | B2: =Q19 -> 5065 | F2: Kerättävä määrä | G2: =Q20 -> 997 | K2: Kerättävä määrä | L2: =Q21 -> 440 | P2: Kerättävä määrä | Q2: =Q24 -> 0
A3: Keräysteho kpl/h | B3: ='Keräysteho kplh'!B2 -> 178 | F3: Keräysteho kpl/h | G3: ='Keräysteho kplh'!B3 -> 73 | K3: Keräysteho kpl/h | L3: ='Keräysteho kplh'!B4 -> 108 | P3: Keräysteho kpl/h | Q3: ='Keräysteho kplh'!B7 -> 32
A5: Vuoron päättymisaika | C5: Aikaa jäljellä (h) | D5: keräystunnit jäljellä | F5: Vuoron päättymisaika | H5: Aikaa jäljellä (h) | I5: keräystunnit jäljellä | K5: Vuoron päättymisaika | M5: Aikaa jäljellä (h) | N5: keräystunnit jäljellä | P5: Vuoron päättymisaika | R5: Aikaa jäljellä (h) | S5: keräystunnit jäljellä
A6: =TODAY()+TIME(12,0,0) -> 46315.5 | B6: 1 | C6: =A6-B11 -> 0.10458981 | D6: =B6*C6 -> 0.10458981 | F6: =TODAY()+TIME(12,0,0) -> 46315.5 | G6: 3 | H6: =F6-G11 -> 0.10458981 | I6: =G6*H6 -> 0.31376944 | K6: =TODAY()+TIME(12,0,0) -> 46315.5 | L6: 0 | M6: =K6-L11 -> 0.10458981 | N6: =L6*M6 -> 0 | P6: =TODAY()+TIME(12,0,0) -> 46315.5 | Q6: 2 | R6: =P6-Q11 -> 0.10458981 | S6: =Q6*R6 -> 0.20917963
A7: =TODAY()+TIME(13,0,0) -> 46315.542 | B7: 6 | C7: =A7-B11 -> 0.14625648 | D7: =B7*C7 -> 0.87753889 | F7: =TODAY()+TIME(13,0,0) -> 46315.542 | G7: 8 | H7: =F7-G11 -> 0.14625648 | I7: =G7*H7 -> 1.1700519 | K7: =TODAY()+TIME(13,0,0) -> 46315.542 | L7: 3 | M7: =K7-L11 -> 0.14625648 | N7: =L7*M7 -> 0.43876944 | P7: =TODAY()+TIME(13,0,0) -> 46315.542 | Q7: 0 | R7: =P7-Q11 -> 0.14625648 | S7: =Q7*R7 -> 0
A8: =TODAY()+TIME(14,0,0) -> 46315.583 | B8: 0 | C8: =A8-B11 -> 0.18792315 | D8: =B8*C8 -> 0 | F8: =TODAY()+TIME(14,0,0) -> 46315.583 | G8: 1 | H8: =F8-G11 -> 0.18792315 | I8: =G8*H8 -> 0.18792315 | K8: =TODAY()+TIME(14,0,0) -> 46315.583 | L8: 0 | M8: =K8-L11 -> 0.18792315 | N8: =L8*M8 -> 0 | P8: =TODAY()+TIME(14,0,0) -> 46315.583 | Q8: 0 | R8: =P8-Q11 -> 0.18792315 | S8: =Q8*R8 -> 0
A9: =TODAY()+TIME(15,0,0) -> 46315.625 | B9: 4 | C9: =A9-B11 -> 0.22958981 | D9: =B9*C9 -> 0.91835926 | F9: =TODAY()+TIME(15,0,0) -> 46315.625 | G9: 0 | H9: =F9-G11 -> 0.22958981 | I9: =G9*H9 -> 0 | K9: =TODAY()+TIME(15,0,0) -> 46315.625 | L9: 1 | M9: =K9-L11 -> 0.22958981 | N9: =L9*M9 -> 0.22958981 | P9: =TODAY()+TIME(15,0,0) -> 46315.625 | Q9: 0 | R9: =P9-Q11 -> 0.22958981 | S9: =Q9*R9 -> 0
A11: Nykyinen aika | B11: =NOW() -> 46315.395 | F11: Nykyinen aika | G11: =NOW() -> 46315.395 | K11: Nykyinen aika | L11: =NOW() -> 46315.395 | P11: Nykyinen aika | Q11: =NOW() -> 46315.395
A13: Kokonaistyötunnit (Jäljellä) | B13: =(B6*C6)+(B7*C7)+(B8*C8)+(B9*C9) -> 1.900488 | C13: Kerääjät / yht | D13: =B9+B8+B7+B6 -> 11 | F13: Kokonaistyötunnit (Jäljellä) | G13: =(H9*G9)+(H8*G8)+(H7*G7)+(H6*G6) -> 1.6717444 | H13: Kerääjät / yht | I13: =G9+G8+G7+G6 -> 12 | K13: Kokonaistyötunnit (Jäljellä) | L13: =N9+N8+N7+N6 -> 0.66835926 | M13: Kerääjät / yht | N13: =L9+L8+L7+L6 -> 4 | P13: Kokonaistyötunnit (Jäljellä) | Q13: =S9+S8+S7+S6 -> 0.20917963 | R13: Kerääjät / yht | S13: =Q9+Q8+Q7+Q6 -> 2
A14: Tuotteita / kerääjä | B14: =B2/(B6+B7+B8+B9) -> 460.45455 | F14: Tuotteita / kerääjä | G14: =G2/(G6+G7+G8+G9) -> 83.083333 | K14: Tuotteita / kerääjä | L14: =L2/(L6+L7+L8+L9) -> 110 | P14: Tuotteita / kerääjä | Q14: =Q2/(Q6+Q7+Q8+Q9) -> 0
A15: Arvioitu kesto (Tunnit) | B15: =B2/(B3*(B6+B7+B8+B9))/24 -> 0.1077843 | F15: Arvioitu kesto (Tunnit) | G15: =G2/(G3*(G6+G7+G8+G9))/24 -> 0.047421994 | K15: Arvioitu kesto (Tunnit) | L15: =L2/(L3*(L6+L7+L8+L9))/24 -> 0.042438272 | P15: Arvioitu kesto (Tunnit) | Q15: =Q2/(Q3*(Q6+Q7+Q8+Q9))/24 -> 0
A16: Arvioitu valmistuminen | B16: =B11+B15 -> 46315.503 | F16: Arvioitu valmistuminen | G16: =G11+G15 -> 46315.443 | K16: Arvioitu valmistuminen | L16: =L11+L15 -> 46315.438 | P16: Arvioitu valmistuminen | Q16: =Q11+Q15 -> 46315.395
A18: LÄMMIN AUTO | F18: KYLMÄ AUTO | K18: KOKONAIS | P18: KERÄTTÄVÄ MÄÄRÄ | R18: ARVIOITU VALMISTUMINEN
A19: Kerättävä määrä | B19: =Q22 -> 2615 | F19: Kerättävä määrä | G19: =Q23 -> 1750 | K19: Lisätyötarve HH:MM | L19: =((N21-N20)/L20)/24 -> -2.4324636 | M19: Lisätyötuntikapa | N19: =N20+($L$20*L21) -> 20484.142 | P19: MASSA | Q19: 5065 | R19: MASSA | S19: =B16 -> 46315.503
A20: Keräysteho kpl/h | B20: ='Keräysteho kplh'!B5 -> 449 | F20: Keräysteho kpl/h | G20: ='Keräysteho kplh'!B6 -> 401 | K20: Keräysteho kpl/h | L20: =(B3*B13+G3*G13+L3*L13+Q3*Q13+B20*B30+G20*G30)/ (B13+G13+L13+Q13+B30+G30) -> 164.73597 | M20: Keräyskapa | N20: =L20*L30*24 -> 20484.142 | P20: KAUPPA | Q20: 997 | R20: KAUPPA | S20: =G16 -> 46315.443
K21: Lisätunnit | L21: 0 | M21: Kerättävä määrä | N21: =B2+G2+L2+Q2+B19+G19 -> 10867 | P21: PAKASTE | Q21: 440 | R21: PAKASTE | S21: =L16 -> 46315.438
A22: Vuoron päättymisaika | C22: Aikaa jäljellä (h) | D22: keräystunnit jäljellä | F22: Vuoron päättymisaika | H22: Aikaa jäljellä (h) | I22: keräystunnit jäljellä | K22: Vuoron päättymisaika | L22: HKL | M22: Aikaa jäljellä (h) | N22: keräystunnit jäljellä | P22: LÄMMIN AUTO | Q22: 2615 | R22: LÄMMIN AUTO | S22: =B33 -> 46315.476 | T22: 47
A23: =TODAY()+TIME(12,0,0) -> 46315.5 | B23: 1 | C23: =A23-B28 -> 0.10458981 | D23: =B23*C23 -> 0.10458981 | F23: =TODAY()+TIME(12,0,0) -> 46315.5 | G23: 0 | H23: =F23-G28 -> 0.10458981 | I23: =G23*H23 -> 0 | K23: =TODAY()+TIME(12,0,0) -> 46315.5 | L23: =G23+B23+B6+G6+L6+Q6 -> 7 | M23: =K23-L28 -> 0.10458981 | N23: =L23*M23 -> 0.7321287 | P23: KYLMÄ AUTO | Q23: 1750 | R23: KYLMÄ AUTO | S23: =G33 -> 46315.486
A24: =TODAY()+TIME(13,0,0) -> 46315.542 | B24: 1 | C24: =A24-B28 -> 0.14625648 | D24: =B24*C24 -> 0.14625648 | F24: =TODAY()+TIME(13,0,0) -> 46315.542 | G24: 2 | H24: =F24-G28 -> 0.14625648 | I24: =G24*H24 -> 0.29251296 | K24: =TODAY()+TIME(13,0,0) -> 46315.542 | L24: =G24+B24+B7+G7+L7+Q7 -> 20 | M24: =K24-L28 -> 0.14625648 | N24: =L24*M24 -> 2.9251296 | P24: KÄYTTÖTAVARA | Q24: 0 | R24: KÄYTTÖTAVARA | S24: =Q16 -> 46315.395
A25: =TODAY()+TIME(14,0,0) -> 46315.583 | B25: 1 | C25: =A25-B28 -> 0.18792315 | D25: =B25*C25 -> 0.18792315 | F25: =TODAY()+TIME(14,0,0) -> 46315.583 | G25: 0 | H25: =F25-G28 -> 0.18792315 | I25: =G25*H25 -> 0 | K25: =TODAY()+TIME(14,0,0) -> 46315.583 | L25: =G25+B25+B8+G8+L8+Q8 -> 2 | M25: =K25-L28 -> 0.18792315 | N25: =L25*M25 -> 0.3758463 | P25: KOKONAIS | Q25: =Q19+Q20+Q21+Q22+Q23+Q24 -> 10867 | R25: KOKONAIS | S25: =L33 -> 46315.503
A26: =TODAY()+TIME(15,0,0) -> 46315.625 | B26: 0 | C26: =A26-B28 -> 0.22958981 | D26: =B26*C26 -> 0 | F26: =TODAY()+TIME(15,0,0) -> 46315.625 | G26: 0 | H26: =F26-G28 -> 0.22958981 | I26: =G26*H26 -> 0 | K26: =TODAY()+TIME(15,0,0) -> 46315.625 | L26: =G26+B26+B9+G9+L9+Q9 -> 5 | M26: =K26-L28 -> 0.22958981 | N26: =L26*M26 -> 1.1479491 | P26: Arvioitu aika | R26: Kierroksia
P27: LAATIKOITA JÄLJELLÄ | R27: KIERROKSIA JÄLJELLÄ
A28: Nykyinen aika | B28: =NOW() -> 46315.395 | F28: Nykyinen aika | G28: =NOW() -> 46315.395 | K28: Nykyinen aika | L28: =NOW() -> 46315.395 | M28: Ylim. Työaika | N28: =L30-N21/L20/24 -> 2.4324636 | P28: XL MASSA | Q28: 0 | R28: KIERROKSIA | S28: =Q28/25 -> 0
P29: MASSA | Q29: 0 | R29: KIERROKSIA | S29: =B40 -> 0
A30: Kokonaistyötunnit (Jäljellä) | B30: =D26+D25+D24+D23 -> 0.43876944 | C30: Kerääjät / yht | D30: =B26+B25+B24+B23 -> 3 | F30: Kokonaistyötunnit (Jäljellä) | G30: =I26+I25+I24+I23 -> 0.29251296 | H30: Kerääjät / yht | I30: =G26+G25+G24+G23 -> 2 | K30: Kokonaistyötunnit (Jäljellä) | L30: =N23+N24+N25+N26 -> 5.1810537 | M30: Kerääjät / yht | N30: =L26+L25+L24+L23 -> 34 | P30: KAUPPA | Q30: 0 | R30: KIERROKSIA | S30: =G40 -> 0
A31: Tuotteita / kerääjä | B31: =B19/(B23+B24+B25+B26) -> 871.66667 | F31: Tuotteita / kerääjä | G31: =G19/(G23+G24+G25+G26) -> 875 | K31: Tuotteita / kerääjä | L31: =N21/(L23+L24+L25+L26) -> 319.61765 | P31: PAKASTE | Q31: 0 | R31: PSS | S31: -
A32: Arvioitu kesto (Tunnit) | B32: =B19/(B20*(B23+B24+B25+B26))/24 -> 0.080889631 | F32: Arvioitu kesto (Tunnit) | G32: =G19/(G20*(G23+G24+G25+G26))/24 -> 0.090918537 | K32: Arvioitu kesto HH:MM | L32: =MAX(IFERROR(G32,"0"),IFERROR(B32,"0"),IFERROR(L15,"0"),IFERROR(G15,"0"),IFERROR(B15,"0"),IFERROR(Q15,"0")) -> 0.1077843 | M32: Tarvittavat työtunnit | N32: =N21/L20/24 -> 2.7485901 | P32: LÄMMIN AUTO | Q32: 0 | R32: RULLAKOITA | S32: =B46 -> 0
A33: Arvioitu valmistuminen | B33: =B28+B32 -> 46315.476 | F33: Arvioitu valmistuminen | G33: =G28+G32 -> 46315.486 | K33: Arvioitu valmistuminen | L33: =MAX(IFERROR(G33,"0"),IFERROR(B33,"0"),IFERROR(L16,"0"),IFERROR(G16,"0"),IFERROR(B16,"0"),IFERROR(Q16,"0")) -> 46315.503 | P33: KYLMÄ AUTO | Q33: 0 | R33: RULLAKOITA | S33: =G46 -> 0
P34: KÄYTTÖTAVARA | Q34: 0 | R34: KIERROKSIA | S34: =L46 -> 0
P35: KOKONAIS | Q35: =B39+G39+L39+L45+G45+B45 -> 0
P36: ~ Per kerääjä | Q36: =Q35/N30 -> 0 | R36: PER KERÄÄJÄ
A37: MASSA | F37: KAUPPA | K37: PAKASTE | R37: KIERROKSIA | S37: =S29/D13 -> 0
A38: Tuotteita | B38: =B2 -> 5065 | C38: Kerääjät / yht | D38: =D13 -> 11 | F38: Tuotteita | G38: =G2 -> 997 | H38: Kerääjät / yht | I38: =I13 -> 12 | K38: Tuotteita | L38: =L2 -> 440 | M38: Kerääjät / yht | N38: =N13 -> 4 | R38: KIERROKSIA | S38: =S30/I13 -> 0
A39: Laatikoita | B39: =Q28 -> 0 | F39: Laatikoita | G39: =Q29 -> 0 | K39: Pss/laatikoita | L39: =Q30 -> 0 | R39: ~ PER KERÄÄJÄ | S39: =L40 -> 0
A40: Kierroksia | B40: =B39/9 -> 0 | F40: Kierroksia | G40: =G39/9 -> 0 | K40: ~ Per kerääjä | L40: =L39/N13 -> 0 | R40: RULLAKOITA | S40: =S32/D30 -> 0
A41: Kierroksia/kerääjä | B41: =B40/D13 -> 0 | F41: Kierroksia/kerääjä | G41: =G40/I13 -> 0 | R41: RULLAKOITA | S41: =S33/I30 -> 0
R42: KIERROKSIA | S42: =S34/S13 -> 0
A43: LÄMMIN AUTO | F43: KYLMÄ AUTO | K43: KÄYTTÖTAVARA
A44: Tuotteita | B44: =B19 -> 2615 | C44: Kerääjät / yht | D44: =D19 -> 0 | F44: Tuotteita | G44: =G19 -> 1750 | H44: Kerääjät / yht | I44: =I19 -> 0 | K44: Tuotteita | L44: =Q2 -> 0 | M44: Kerääjät / yht | N44: =S13 -> 2
...

Sheet Vanhempi versio
A1: MASSA | F1: KAUPPA | K1: PAKASTE | P1: KÄYTTÖTAVARA
A2: Kerättävä määrä | B2: =Q13 -> 0 | F2: Kerättävä määrä | G2: =Q14 -> 0 | K2: Kerättävä määrä | L2: =Q15 -> 0 | P2: Kerättävä määrä | Q2: =Q18 -> 0
A3: Keräysteho kpl/h | B3: ='Keräysteho kplh'!B2 -> 178 | F3: Keräysteho kpl/h | G3: ='Keräysteho kplh'!B3 -> 73 | K3: Keräysteho kpl/h | L3: ='Keräysteho kplh'!B4 -> 108 | P3: Keräysteho kpl/h | Q3: ='Keräysteho kplh'!B7 -> 32
A5: Vuoron päättymisaika | B5: HKL | C5: Aikaa jäljellä (h) | D5: keräystunnit jäljellä | F5: Vuoron päättymisaika | G5: HKL | H5: Aikaa jäljellä (h) | I5: keräystunnit jäljellä | K5: Vuoron päättymisaika | L5: HKL | M5: Aikaa jäljellä (h) | N5: keräystunnit jäljellä | P5: Vuoron päättymisaika | R5: Aikaa jäljellä (h) | S5: keräystunnit jäljellä
A6: =TODAY()+TIME(12,0,0) -> 46315.5 | B6: 0 | C6: =A6-B11 -> 0.10458981 | D6: =B6*C6 -> 0 | F6: =TODAY()+TIME(12,0,0) -> 46315.5 | G6: 0 | H6: =F6-G11 -> 0.10458981 | I6: =G6*H6 -> 0 | K6: =TODAY()+TIME(12,0,0) -> 46315.5 | L6: 0 | M6: =K6-L11 -> 0.10458981 | N6: =L6*M6 -> 0 | P6: =S18 -> #DIV/0! | Q6: 0 | R6: =P6-L29 -> #DIV/0! | S6: =R6*Q6 -> #DIV/0!
A7: =TODAY()+TIME(13,0,0) -> 46315.542 | B7: 0 | C7: =A7-B11 -> 0.14625648 | D7: =B7*C7 -> 0 | F7: =TODAY()+TIME(13,0,0) -> 46315.542 | G7: 0 | H7: =F7-G11 -> 0.14625648 | I7: =G7*H7 -> 0 | K7: =TODAY()+TIME(13,0,0) -> 46315.542 | L7: 0 | M7: =K7-L11 -> 0.14625648 | N7: =L7*M7 -> 0 | P7: Kokonaistyötunnit (Jäljellä) | Q7: =S6 -> #DIV/0! | R7: Kerääjät / yht | S7: =Q6 -> 0
A8: =TODAY()+TIME(14,0,0) -> 46315.583 | B8: 0 | C8: =A8-B11 -> 0.18792315 | D8: =B8*C8 -> 0 | F8: =TODAY()+TIME(14,0,0) -> 46315.583 | G8: 0 | H8: =F8-G11 -> 0.18792315 | I8: =G8*H8 -> 0 | K8: =TODAY()+TIME(14,0,0) -> 46315.583 | L8: 0 | M8: =K8-L11 -> 0.18792315 | N8: =L8*M8 -> 0 | P8: Tuotteita / kerääjä | Q8: =Q2/(Q6) -> #DIV/0!
A9: =TODAY()+TIME(15,0,0) -> 46315.625 | B9: 0 | C9: =A9-B11 -> 0.22958981 | D9: =B9*C9 -> 0 | F9: =TODAY()+TIME(15,0,0) -> 46315.625 | G9: 0 | H9: =F9-G11 -> 0.22958981 | I9: =G9*H9 -> 0 | K9: =TODAY()+TIME(15,0,0) -> 46315.625 | L9: 0 | M9: =K9-L11 -> 0.22958981 | N9: =L9*M9 -> 0 | P9: Arvioitu kesto (Tunnit) | Q9: =Q2/(Q3*(Q6))/24 -> #DIV/0!
P10: Arvioitu valmistuminen | Q10: =L29+Q9 -> #DIV/0!
A11: Nykyinen aika | B11: =NOW() -> 46315.395 | F11: Nykyinen aika | G11: =NOW() -> 46315.395 | K11: Nykyinen aika | L11: =NOW() -> 46315.395
P12: KERÄTTÄVÄ MÄÄRÄ | R12: ARVIOITU VALMISTUMINEN
A13: Kokonaistyötunnit (Jäljellä) | B13: =(B6*C6)+(B7*C7)+(B8*C8)+(B9*C9) -> 0 | C13: Kerääjät / yht | D13: =B9+B8+B7+B6 -> 0 | F13: Kokonaistyötunnit (Jäljellä) | G13: =(H9*G9)+(H8*G8)+(H7*G7)+(H6*G6) -> 0 | H13: Kerääjät / yht | I13: =G9+G8+G7+G6 -> 0 | K13: Kokonaistyötunnit (Jäljellä) | L13: =N9+N8+N7+N6 -> 0 | M13: Kerääjät / yht | N13: =L9+L8+L7+L6 -> 0 | P13: MASSA | Q13: 0 | R13: MASSA | S13: =B16 -> #DIV/0!
A14: Tuotteita / kerääjä | B14: =B2/(B6+B7+B8+B9) -> #DIV/0! | F14: Tuotteita / kerääjä | G14: =G2/(G6+G7+G8+G9) -> #DIV/0! | K14: Tuotteita / kerääjä | L14: =L2/(L6+L7+L8+L9) -> #DIV/0! | P14: KAUPPA | Q14: 0 | R14: KAUPPA | S14: =G16 -> #DIV/0!
A15: Arvioitu kesto (Tunnit) | B15: =B2/(B3*(B6+B7+B8+B9))/24 -> #DIV/0! | F15: Arvioitu kesto (Tunnit) | G15: =G2/(G3*(G6+G7+G8+G9))/24 -> #DIV/0! | K15: Arvioitu kesto (Tunnit) | L15: =L2/(L3*(L6+L7+L8+L9))/24 -> #DIV/0! | P15: PAKASTE | Q15: 0 | R15: PAKASTE | S15: =L16 -> #DIV/0!
A16: Arvioitu valmistuminen | B16: =B11+B15 -> #DIV/0! | F16: Arvioitu valmistuminen | G16: =G11+G15 -> #DIV/0! | K16: Arvioitu valmistuminen | L16: =L11+L15 -> #DIV/0! | P16: LÄMMIN AUTO | Q16: 0 | R16: LÄMMIN AUTO | S16: =B33 -> #DIV/0!
P17: KYLMÄ AUTO | Q17: 0 | R17: KYLMÄ AUTO | S17: =G33 -> #DIV/0!
A18: LÄMMIN AUTO | F18: KYLMÄ AUTO | K18: KOKONAIS ET | P18: KÄYTTÖTAVARA | Q18: 0 | R18: KÄYTTÖTAVARA | S18: =Q10 -> #DIV/0!
A19: Kerättävä määrä | B19: =Q16 -> 0 | F19: Kerättävä määrä | G19: =Q17 -> 0 | K19: Lisätyötarve HH:MM | L19: =((N21-N20)/L20)/24 -> #DIV/0! | M19: Lisätyötuntikapa | N19: =N20+($L$20*L21) -> #DIV/0! | P19: KOKONAIS | Q19: =Q13+Q14+Q15+Q16+Q17+Q18 -> 0 | R19: KOKONAIS | S19: =L33 -> 0
A20: Keräysteho kpl/h | B20: ='Keräysteho kplh'!B5 -> 449 | F20: Keräysteho kpl/h | G20: ='Keräysteho kplh'!B6 -> 401 | K20: Keräysteho kpl/h ET | L20: =(B3*B13+G3*G13+L3*L13+B20*B30+G20*G30)/ (B13+G13+L13+B30+G30) -> #DIV/0! | M20: Keräyskapa | N20: =L20*L30*24 -> #DIV/0! | P20: Arvioitu aika | R20: Kierroksia
K21: Lisätunnit | L21: 0 | M21: Kerättävä määrä ET | N21: =B2+G2+L2+B19+G19 -> 0 | P21: LAATIKOITA JÄLJELLÄ | R21: KIERROKSIA JÄLJELLÄ
A22: Vuoron päättymisaika | B22: HKL | C22: Aikaa jäljellä (h) | D22: keräystunnit jäljellä | F22: Vuoron päättymisaika | G22: HKL | H22: Aikaa jäljellä (h) | I22: keräystunnit jäljellä | K22: Keräysteho kpl/h ET + KT | L22: =(B3*B13+G3*G13+L3*L13+Q3*Q7+B20*B30+G20*G30)/ (B13+G13+L13+Q7+B30+G30) -> #DIV/0! | M22: Kerättävä määrä ET + KT | N22: =B2+G2+L2+Q2+B19+G19 -> 0 | P22: XL MASSA | Q22: 0 | R22: KIERROKSIA | S22: =Q22/25 -> 0 | T22: 47
A23: =TODAY()+TIME(12,0,0) -> 46315.5 | B23: 0 | C23: =A23-B28 -> 0.10458981 | D23: =B23*C23 -> 0 | F23: =TODAY()+TIME(12,0,0) -> 46315.5 | G23: 0 | H23: =F23-G28 -> 0.10458981 | I23: =G23*H23 -> 0 | K23: Vuoron päättymisaika | L23: HKL ET | M23: Aikaa jäljellä (h) | N23: keräystunnit jäljellä | P23: MASSA | Q23: 0 | R23: KIERROKSIA | S23: =B40 -> 0
A24: =TODAY()+TIME(13,0,0) -> 46315.542 | B24: 0 | C24: =A24-B28 -> 0.14625648 | D24: =B24*C24 -> 0 | F24: =TODAY()+TIME(13,0,0) -> 46315.542 | G24: 0 | H24: =F24-G28 -> 0.14625648 | I24: =G24*H24 -> 0 | K24: =TODAY()+TIME(12,0,0) -> 46315.5 | L24: =G23+B23+B6+G6+L6 -> 0 | M24: =K24-L29 -> 0.10458981 | N24: =L24*M24 -> 0 | P24: KAUPPA | Q24: 0 | R24: KIERROKSIA | S24: =G40 -> 0
A25: =TODAY()+TIME(14,0,0) -> 46315.583 | B25: 0 | C25: =A25-B28 -> 0.18792315 | D25: =B25*C25 -> 0 | F25: =TODAY()+TIME(14,0,0) -> 46315.583 | G25: 0 | H25: =F25-G28 -> 0.18792315 | I25: =G25*H25 -> 0 | K25: =TODAY()+TIME(13,0,0) -> 46315.542 | L25: =G24+B24+B7+G7+L7 -> 0 | M25: =K25-L29 -> 0.14625648 | N25: =L25*M25 -> 0 | P25: PAKASTE | Q25: 0 | R25: PSS | S25: -
A26: =TODAY()+TIME(15,0,0) -> 46315.625 | B26: 0 | C26: =A26-B28 -> 0.22958981 | D26: =B26*C26 -> 0 | F26: =TODAY()+TIME(15,0,0) -> 46315.625 | G26: 0 | H26: =F26-G28 -> 0.22958981 | I26: =G26*H26 -> 0 | K26: =TODAY()+TIME(14,0,0) -> 46315.583 | L26: =G25+B25+B8+G8+L8 -> 0 | M26: =K26-L29 -> 0.18792315 | N26: =L26*M26 -> 0 | P26: LÄMMIN AUTO | Q26: 0 | R26: RULLAKOITA | S26: =B46 -> 0
K27: =TODAY()+TIME(15,0,0) -> 46315.625 | L27: =G26+B26+B9+G9+L9 -> 0 | M27: =K27-L29 -> 0.22958981 | N27: =L27*M27 -> 0 | P27: KYLMÄ AUTO | Q27: 0 | R27: RULLAKOITA | S27: =G46 -> 0
A28: Nykyinen aika | B28: =NOW() -> 46315.395 | F28: Nykyinen aika | G28: =NOW() -> 46315.395 | K28: HKL KT | L28: =S7 -> 0 | M28: =R6 -> #DIV/0! | N28: =S6 -> #DIV/0! | P28: KÄYTTÖTAVARA | Q28: 0 | R28: KIERROKSIA | S28: =L46 -> 0
K29: Nykyinen aika | L29: =NOW() -> 46315.395 | M29: Ylim. Työaika | N29: =L30-N21/L20/24 -> #DIV/0! | P29: KOKONAIS | Q29: =B39+G39+L39+L45+G45+B45 -> 0
A30: Kokonaistyötunnit (Jäljellä) | B30: =D26+D25+D24+D23 -> 0 | C30: Kerääjät / yht | D30: =B26+B25+B24+B23 -> 0 | F30: Kokonaistyötunnit (Jäljellä) | G30: =I26+I25+I24+I23 -> 0 | H30: Kerääjät / yht | I30: =G26+G25+G24+G23 -> 0 | K30: Kokonaistyötunnit (Jäljellä) | L30: =N24+N25+N26+N27 -> 0 | M30: Kerääjät / yht | N30: =L27+L26+L25+L24 -> 0 | P30: ~ Per kerääjä | Q30: =Q29/N30 -> #DIV/0! | R30: PER KERÄÄJÄ
A31: Tuotteita / kerääjä | B31: =B19/(B23+B24+B25+B26) -> #DIV/0! | F31: Tuotteita / kerääjä | G31: =G19/(G23+G24+G25+G26) -> #DIV/0! | K31: Tuotteita / kerääjä | L31: =N21/(L24+L25+L26+L27) -> #DIV/0! | R31: KIERROKSIA | S31: =S23/D13 -> #DIV/0!
A32: Arvioitu kesto (Tunnit) | B32: =B19/(B20*(B23+B24+B25+B26))/24 -> #DIV/0! | F32: Arvioitu kesto (Tunnit) | G32: =G19/(G20*(G23+G24+G25+G26))/24 -> #DIV/0! | K32: Arvioitu kesto HH:MM | L32: =MAX(IFERROR(G32,"0"),IFERROR(B32,"0"),IFERROR(L15,"0"),IFERROR(G15,"0"),IFERROR(B15,"0"),IFERROR(Q9,"0")) -> 0 | M32: Tarvittavat työtunnit | N32: =N21/L20/24 -> #DIV/0! | R32: KIERROKSIA | S32: =S24/I13 -> #DIV/0!
A33: Arvioitu valmistuminen | B33: =B28+B32 -> #DIV/0! | F33: Arvioitu valmistuminen | G33: =G28+G32 -> #DIV/0! | K33: Arvioitu valmistuminen | L33: =MAX(IFERROR(G33,"0"),IFERROR(B33,"0"),IFERROR(L16,"0"),IFERROR(G16,"0"),IFERROR(B16,"0"),IFERROR(Q10,"0")) -> 0 | R33: ~ PER KERÄÄJÄ | S33: =L40 -> #DIV/0!
R34: RULLAKOITA | S34: =S26/D30 -> #DIV/0!
R35: RULLAKOITA | S35: =S27/I30 -> #DIV/0!
R36: KIERROKSIA | S36: =S28/S7 -> #DIV/0!
A37: MASSA | F37: KAUPPA | K37: PAKASTE
A38: Tuotteita | B38: =B2 -> 0 | C38: Kerääjät / yht | D38: =D13 -> 0 | F38: Tuotteita | G38: =G2 -> 0 | H38: Kerääjät / yht | I38: =I13 -> 0 | K38: Tuotteita | L38: =L2 -> 0 | M38: Kerääjät / yht | N38: =N13 -> 0
A39: Laatikoita | B39: =Q23 -> 0 | F39: Laatikoita | G39: =Q24 -> 0 | K39: Pss/laatikoita | L39: =Q25 -> 0
A40: Kierroksia | B40: =B39/9 -> 0 | F40: Kierroksia | G40: =G39/9 -> 0 | K40: ~ Per kerääjä | L40: =L39/N13 -> #DIV/0!
A41: Kierroksia/kerääjä | B41: =B40/D13 -> #DIV/0! | F41: Kierroksia/kerääjä | G41: =G40/I13 -> #DIV/0!
...

Sheet BACKUP
A1: 2 | F1: KAUPPA | K1: PAKASTE | P1: KÄYTTÖTAVARA
A2: Kerättävä määrä | B2: =Q12 -> 0 | F2: Kerättävä määrä | G2: =Q13 -> 0 | K2: Kerättävä määrä | L2: =Q14 -> 0 | P2: Kerättävä määrä | Q2: =Q17 -> 0
A3: Keräysteho kpl/h | B3: ='Keräysteho kplh'!B2 -> 178 | F3: Keräysteho kpl/h | G3: ='Keräysteho kplh'!B3 -> 73 | K3: Keräysteho kpl/h | L3: ='Keräysteho kplh'!B4 -> 108 | P3: Keräysteho kpl/h | Q3: ='Keräysteho kplh'!B7 -> 32
A4: Vuoron päättymisaika | B4: HKL | C4: Aikaa jäljellä (h) | D4: keräystunnit jäljellä | F4: Vuoron päättymisaika | G4: HKL | H4: Aikaa jäljellä (h) | I4: keräystunnit jäljellä | K4: Vuoron päättymisaika | L4: HKL | M4: Aikaa jäljellä (h) | N4: keräystunnit jäljellä | P4: Vuoron päättymisaika | R4: Aikaa jäljellä (h) | S4: keräystunnit jäljellä
A5: =TODAY()+TIME(11,0,0) -> 46315.458 | B5: 0 | C5: =A5-D13 -> 0.062923148 | D5: =B5*C5 -> 0 | F5: =TODAY()+TIME(11,0,0) -> 46315.458 | G5: 0 | H5: =F5-I13 -> 0.062923148 | I5: =G5*H5 -> 0 | K5: =TODAY()+TIME(11,0,0) -> 46315.458 | L5: 0 | M5: =K5-N13 -> 0.062923148 | N5: =L5*M5 -> 0 | P5: =S17 | Q5: 0 | R5: =P5-L25 -> #VALUE! | S5: =R5*Q5 -> #VALUE!
A6: =TODAY()+TIME(12,0,0) -> 46315.5 | B6: 0 | C6: =A6-D13 -> 0.10458981 | D6: =B6*C6 -> 0 | F6: =TODAY()+TIME(12,0,0) -> 46315.5 | G6: 0 | H6: =F6-I13 -> 0.10458981 | I6: =G6*H6 -> 0 | K6: =TODAY()+TIME(12,0,0) -> 46315.5 | L6: 0 | M6: =K6-N13 -> 0.10458981 | N6: =L6*M6 -> 0 | P6: Kokonaistyötunnit (Jäljellä) | Q6: =S5 -> #VALUE! | R6: Kerääjät / yht | S6: =Q5 -> 0
A7: =TODAY()+TIME(13,0,0) -> 46315.542 | B7: 0 | C7: =A7-D13 -> 0.14625648 | D7: =B7*C7 -> 0 | F7: =TODAY()+TIME(13,0,0) -> 46315.542 | G7: 0 | H7: =F7-I13 -> 0.14625648 | I7: =G7*H7 -> 0 | K7: =TODAY()+TIME(13,0,0) -> 46315.542 | L7: 0 | M7: =K7-N13 -> 0.14625648 | N7: =L7*M7 -> 0 | P7: Tuotteita / kerääjä | Q7: =Q2/(Q5) -> #DIV/0!
A8: =TODAY()+TIME(14,0,0) -> 46315.583 | B8: 0 | C8: =A8-D13 -> 0.18792315 | D8: =B8*C8 -> 0 | F8: =TODAY()+TIME(14,0,0) -> 46315.583 | G8: 0 | H8: =F8-I13 -> 0.18792315 | I8: =G8*H8 -> 0 | K8: =TODAY()+TIME(14,0,0) -> 46315.583 | L8: 0 | M8: =K8-N13 -> 0.18792315 | N8: =L8*M8 -> 0 | P8: Arvioitu kesto (Tunnit) | Q8: =Q2/(Q3*(Q5))/24 -> #DIV/0!
A9: =TODAY()+TIME(15,0,0) -> 46315.625 | B9: 0 | C9: =A9-D13 -> 0.22958981 | D9: =B9*C9 -> 0 | F9: =TODAY()+TIME(15,0,0) -> 46315.625 | G9: 0 | H9: =F9-I13 -> 0.22958981 | I9: =G9*H9 -> 0 | K9: =TODAY()+TIME(15,0,0) -> 46315.625 | L9: 0 | M9: =K9-N13 -> 0.22958981 | N9: =L9*M9 -> 0 | P9: Arvioitu valmistuminen | Q9: =IFERROR(L25+Q8+IF(Q2>=400,TIME(0,24,0),0),"")
A10: Kokonaistyötunnit (Jäljellä) | B10: =D5+D6+D7+D8+D9 -> 0 | C10: Kerääjät / yht | D10: =B9+B8+B7+B6+B5 -> 0 | F10: Kokonaistyötunnit (Jäljellä) | G10: =I5+I6+I7+I8+I9 -> 0 | H10: Kerääjät / yht | I10: =G9+G8+G7+G6+G5 -> 0 | K10: Kokonaistyötunnit (Jäljellä) | L10: =N9+N8+N7+N6+N5 -> 0 | M10: Kerääjät / yht | N10: =L9+L8+L7+L6+L5 -> 0
A11: Tuotteita / kerääjä | B11: =B2/(B6+B7+B8+B9) -> #DIV/0! | F11: Tuotteita / kerääjä | G11: =G2/(G6+G7+G8+G9) -> #DIV/0! | K11: Tuotteita / kerääjä | L11: =L2/(L6+L7+L8+L9) -> #DIV/0! | P11: KERÄTTÄVÄ MÄÄRÄ | R11: ARVIOITU VALMISTUMINEN
A12: Arvioitu kesto (Tunnit) | B12: =B2/(B3*(B6+B7+B8+B9+B5))/24 -> #DIV/0! | F12: Arvioitu kesto (Tunnit) | G12: =G2/(G3*(G6+G7+G8+G9+G5))/24 -> #DIV/0! | K12: Arvioitu kesto (Tunnit) | L12: =L2/(L3*(L6+L7+L8+L9+L5))/24 -> #DIV/0! | P12: MASSA | Q12: 0 | R12: MASSA | S12: =B13
A13: Arvioitu valmistuminen | B13: =IFERROR(D13+B12+IF(B2>=3000,TIME(0,24,0),0),"") | C13: Nykyinen aika | D13: =NOW() -> 46315.395 | F13: Arvioitu valmistuminen | G13: =IFERROR(I13+G12+IF(G2>=1500,TIME(0,24,0),0),"") | H13: Nykyinen aika | I13: =NOW() -> 46315.395 | K13: Arvioitu valmistuminen | L13: =IFERROR(N13+L12+IF(L2>=400,TIME(0,24,0),0),"") | M13: Nykyinen aika | N13: =NOW() -> 46315.395 | P13: KAUPPA | Q13: 0 | R13: KAUPPA | S13: =G13
P14: PAKASTE | Q14: 0 | R14: PAKASTE | S14: =L13
A15: LÄMMIN AUTO | F15: KYLMÄ AUTO | K15: Lisätyötarve HH:MM | L15: =N29-N28-(L17/24) -> #DIV/0! | M15: Lisätyötuntikapa | N15: =N16+(L16*L17) -> #DIV/0! | P15: LÄMMIN AUTO | Q15: 0 | R15: LÄMMIN AUTO | S15: =B27 | AB15: =IFERROR(((N17-N16)/L16)/24,0)+IF(AA26<0,-AA26,0) -> 0
A16: Kerättävä määrä | B16: =Q15 -> 0 | F16: Kerättävä määrä | G16: =Q16 -> 0 | K16: Keräysteho kpl/h ET | L16: =(B3*B10+G3*G10+L3*L10+B17*B24+G17*G24)/ (B10+G10+L10+B24+G24) -> #DIV/0! | M16: Keräyskapa | N16: =L16*N28*24 -> #DIV/0! | P16: KYLMÄ AUTO | Q16: 0 | R16: KYLMÄ AUTO | S16: =G27
A17: Keräysteho kpl/h | B17: ='Keräysteho kplh'!B5 -> 449 | F17: Keräysteho kpl/h | G17: ='Keräysteho kplh'!B6 -> 401 | K17: Lisätunnit | M17: Kerättävä määrä ET | N17: =B2+G2+L2+B16+G16 -> 0 | P17: KÄYTTÖTAVARA | Q17: 0 | R17: KÄYTTÖTAVARA | S17: =Q9
A18: Vuoron päättymisaika | B18: HKL | C18: Aikaa jäljellä (h) | D18: keräystunnit jäljellä | F18: Vuoron päättymisaika | G18: HKL | H18: Aikaa jäljellä (h) | I18: keräystunnit jäljellä | K18: Kahvitauot HH:MM | L18: =L26*24/1440 -> 0 | M18: Kerättävä määrä ET + KT | N18: =B2+G2+L2+Q2+B16+G16 -> 0 | P18: KOKONAIS | Q18: =Q12+Q13+Q14+Q15+Q16+Q17 -> 0 | R18: KOKONAIS | S18: =L28 -> 0
A19: =TODAY()+TIME(11,0,0) -> 46315.458 | B19: 0 | C19: =A19-D27 -> 0.062923148 | D19: =B19*C19 -> 0 | F19: =TODAY()+TIME(11,0,0) -> 46315.458 | G19: 0 | H19: =F19-I27 -> 0.062923148 | I19: =G19*H19 -> 0 | K19: Vuoron päättymisaika | L19: HKL ET | M19: Keräysteho kpl/h ET + KT | N19: =(B3*B10+G3*G10+L3*L10+Q3*Q6+B17*B24+G17*G24)/ (B10+G10+L10+Q6+B24+G24) -> #VALUE! | P19: Arvioitu aika | R19: Kierroksia
A20: =TODAY()+TIME(12,0,0) -> 46315.5 | B20: 0 | C20: =A20-D27 -> 0.10458981 | D20: =B20*C20 -> 0 | F20: =TODAY()+TIME(12,0,0) -> 46315.5 | G20: 0 | H20: =F20-I27 -> 0.10458981 | I20: =G20*H20 -> 0 | K20: =TODAY()+TIME(11,0,0) -> 46315.458 | L20: =G19+B19+B5+G5+L5 -> 0 | M20: =K20-L25 -> 0.062923148 | N20: =L20*M20 -> 0 | P20: LAATIKOITA JÄLJELLÄ | R20: KIERROKSIA JÄLJELLÄ
A21: =TODAY()+TIME(13,0,0) -> 46315.542 | B21: 0 | C21: =A21-D27 -> 0.14625648 | D21: =B21*C21 -> 0 | F21: =TODAY()+TIME(13,0,0) -> 46315.542 | G21: 0 | H21: =F21-I27 -> 0.14625648 | I21: =G21*H21 -> 0 | K21: =TODAY()+TIME(12,0,0) -> 46315.5 | L21: =G20+B20+B6+G6+L6 -> 0 | M21: =K21-L25 -> 0.10458981 | N21: =L21*M21 -> 0 | P21: XL MASSA | Q21: 0 | R21: KIERROKSIA | S21: =Q21/25 -> 0
A22: =TODAY()+TIME(14,0,0) -> 46315.583 | B22: 0 | C22: =A22-D27 -> 0.18792315 | D22: =B22*C22 -> 0 | F22: =TODAY()+TIME(14,0,0) -> 46315.583 | G22: 0 | H22: =F22-I27 -> 0.18792315 | I22: =G22*H22 -> 0 | K22: =TODAY()+TIME(13,0,0) -> 46315.542 | L22: =G21+B21+B7+G7+L7 -> 0 | M22: =K22-L25 -> 0.14625648 | N22: =L22*M22 -> 0 | P22: MASSA | Q22: 0 | R22: KIERROKSIA | S22: =B32 -> 0 | T22: 47
A23: =TODAY()+TIME(15,0,0) -> 46315.625 | B23: 0 | C23: =A23-D27 -> 0.22958981 | D23: =B23*C23 -> 0 | F23: =TODAY()+TIME(15,0,0) -> 46315.625 | G23: 0 | H23: =F23-I27 -> 0.22958981 | I23: =G23*H23 -> 0 | K23: =TODAY()+TIME(14,0,0) -> 46315.583 | L23: =G22+B22+B8+G8+L8 -> 0 | M23: =K23-L25 -> 0.18792315 | N23: =L23*M23 -> 0 | P23: KAUPPA | Q23: 0 | R23: KIERROKSIA | S23: =G32 -> 0
A24: Kokonaistyötunnit (Jäljellä) | B24: =D23+D22+D21+D20+D19 -> 0 | C24: Kerääjät / yht | D24: =B23+B22+B21+B20+B19 -> 0 | F24: Kokonaistyötunnit (Jäljellä) | G24: =I23+I22+I21+I20+I19 -> 0 | H24: Kerääjät / yht | I24: =G23+G22+G21+G20+G19 -> 0 | K24: =TODAY()+TIME(15,0,0) -> 46315.625 | L24: =G23+B23+B9+G9+L9 -> 0 | M24: =K24-L25 -> 0.22958981 | N24: =L24*M24 -> 0 | P24: PAKASTE | Q24: 0 | R24: PSS | S24: -
A25: Tuotteita / kerääjä | B25: =B16/(B20+B21+B22+B23) -> #DIV/0! | F25: Tuotteita / kerääjä | G25: =G16/(G20+G21+G22+G23) -> #DIV/0! | K25: Nykyinen aika | L25: =NOW() -> 46315.395 | M25: Ylim. Työaika | N25: =IF(AA25<0,"-","")&INT(ROUND(ABS(AA25)*1440,0)/60)&":"&TEXT(MOD(ROUND(ABS(AA25)*1440,0),60),"00") -> 0:00 | P25: LÄMMIN AUTO | Q25: 0 | R25: RULLAKOITA | S25: =B38 -> 0 | AA25: =N28-IFERROR((B2/B3+G2/G3+L2/L3+B16/B17+G16/G17)/24,0)+L17/24 -> 0
A26: Arvioitu kesto (Tunnit) | B26: =B16/(B17*(B20+B21+B22+B23+B19))/24 -> #DIV/0! | F26: Arvioitu kesto (Tunnit) | G26: =G16/(G17*(G20+G21+G22+G23+G19))/24 -> #DIV/0! | K26: Kerääjät / yht | L26: =L24+L23+L22+L21+L20 -> 0 | M26: Ylim. Työaika - tauko | N26: =IF(AA26<0,"-","")&INT(ROUND(ABS(AA26)*1440,0)/60)&":"&TEXT(MOD(ROUND(ABS(AA26)*1440,0),60),"00") -> 0:00 | P26: KYLMÄ AUTO | Q26: 0 | R26: RULLAKOITA | S26: =D38 -> 0 | AA26: =AA25-L18 -> 0
A27: Arvioitu valmistuminen | B27: =IFERROR(D27+B26+IF(B16>=5000,TIME(0,24,0),0),"") | C27: Nykyinen aika | D27: =NOW() -> 46315.395 | F27: Arvioitu valmistuminen | G27: =IFERROR(I27+G26+IF(G16>=5000,TIME(0,24,0),0),"") | H27: Nykyinen aika | I27: =NOW() -> 46315.395 | K27: Tuotteita / kerääjä | L27: =N17/(L21+L22+L23+L24) -> #DIV/0! | M27: Ylim. Työaika - keskiarvo | N27: =ABS(AA26+AA25)/2 -> 0 | P27: KÄYTTÖTAVARA | Q27: 0 | R27: KIERROKSIA | S27: =L39 -> 0
K28: Arvioitu valmistuminen | L28: =MAX(IFERROR(B27*1,0),IFERROR(G27*1,0),IFERROR(L13*1,0),IFERROR(G13*1,0),IFERROR(B13*1,0),IFERROR(Q9*1,0)) -> 0 | M28: Kokonaistyötunnit (Jäljellä) | N28: =N21+N22+N23+N24+N20 -> 0 | P28: KOKONAIS | Q28: =B31+D31+L34+L38+D37+B37 -> 0 | R28: KOKONAIS | S28: =S27+S26+S25+S23+S22+S21 -> 0
A29: MASSA | F29: KAUPPA | K29: Arvioitu valm. + tauko | L29: =L28+(L18/24) -> 0 | M29: Tarvittavat työtunnit | N29: =N17/L16/24 -> #DIV/0! | P29: ~ Per kerääjä | Q29: =Q28/L26 -> #DIV/0! | R29: ~ Per kerääjä | S29: =S28/L26 -> #DIV/0!
A30: Tuotteita | B30: =B2 -> 0 | C30: Kerääjät / yht | D30: =D10 -> 0 | F30: Tuotteita | G30: =G2 -> 0 | H30: Kerääjät / yht | I30: =I10 -> 0 | K30: Arvioitu valm. keskiarvo | L30: =AVERAGE(L28,L29) -> 0 | M30: Arvioitu kesto HH:MM | N30: =MAX(IFERROR(B26*1,0),IFERROR(G26*1,0),IFERROR(L12*1,0),IFERROR(G12*1,0),IFERROR(B12*1,0),IFERROR(Q8*1,0)) -> 0
A31: Laatikoita | B31: =Q22 -> 0 | F31: Laatikoita | G31: =Q23 -> 0 | P31: RULLAKOITA / LAATIKOITA | R31: PER KERÄÄJÄ
A32: Kierroksia | B32: =B31/9 -> 0 | F32: Kierroksia | G32: =G31/9 -> 0 | K32: PAKASTE | P32: MASSA | R32: KIERROKSIA | S32: =S22/D10 -> #DIV/0!
A33: Kierroksia/kerääjä | B33: =B32/D10 -> #DIV/0! | F33: Kierroksia/kerääjä | G33: =G32/I10 -> #DIV/0! | K33: Tuotteita | L33: =L2 -> 0 | M33: Kerääjät / yht | N33: =N10 -> 0 | P33: KAUPPA | R33: KIERROKSIA | S33: =S23/I10 -> #DIV/0!
K34: Pss/laatikoita | L34: =Q24 -> 0 | M34: ~ Per kerääjä | N34: =L34/N10 -> #DIV/0! | P34: PAKASTE | R34: ~ PER KERÄÄJÄ | S34: =N34 -> #DIV/0!
A35: LÄMMIN AUTO | F35: KYLMÄ AUTO | P35: LÄMMIN AUTO | R35: RULLAKOITA | S35: =S25/D24 -> #DIV/0!
A36: Tuotteita | B36: =B16 -> 0 | C36: Kerääjät / yht | D36: =D16 -> 0 | F36: Tuotteita | G36: =G16 -> 0 | H36: Kerääjät / yht | I36: =I16 -> 0 | K36: KÄYTTÖTAVARA | P36: KYLMÄ AUTO | R36: RULLAKOITA | S36: =S26/I24 -> #DIV/0!
A37: Laatikoita | B37: =Q25 -> 0 | F37: Laatikoita | G37: =Q26 -> 0 | K37: Tuotteita | L37: =Q2 -> 0 | M37: Kerääjät / yht | N37: =S6 -> 0 | P37: KÄYTTÖTAVARA | R37: KIERROKSIA | S37: =S27/S6 -> #DIV/0!
A38: Rullakoita | B38: =B37/10 -> 0 | F38: Rullakoita | G38: =G37/10 -> 0 | K38: Laatikoita | L38: =Q27 -> 0 | P38: =NOW() -> 46315.395 | Q38: ↻ | R38: =I27 -> 46315.395
A39: Rullakoita/kerääjä | B39: =B38/D24 -> #DIV/0! | F39: Rullakoita/kerääjä | G39: =G38/I24 -> #DIV/0! | K39: Kierroksia | L39: =L38/16 -> 0 | M39: Kierroksia/kerääjä | N39: =L39/N37 -> #DIV/0!
P47: Nykyinen aika
...

Sheet EN
A1: MANUAL | F1: INSTORE | K1: FROZEN | P1: NON-FOOD INSTORE
A2: Items to pick | B2: =Q12 -> 0 | F2: Items to pick | G2: =Q13 -> 0 | K2: Items to pick | L2: =Q14 -> 0 | P2: Items to pick | Q2: =Q17 -> 0
A3: Picking Rate pcs/h | B3: ='Keräysteho kplh'!B2 -> 178 | F3: Picking Rate pcs/h | G3: ='Keräysteho kplh'!B3 -> 73 | K3: Picking Rate pcs/h | L3: ='Keräysteho kplh'!B4 -> 108 | P3: Picking Rate pcs/h | Q3: ='Keräysteho kplh'!B7 -> 32
A4: Shift End Time | B4: HC | C4: Time Remaining (H) | D4: Hours Remaining | F4: Shift End Time | G4: HC | H4: Time Remaining (H) | I4: Hours Remaining | K4: Shift End Time | L4: HC | M4: Time Remaining (H) | N4: Hours Remaining | P4: Shift End Time | Q4: HC | R4: Time Remaining (H) | S4: Hours Remaining
A5: =TODAY()+TIME(11,0,0) -> 46315.458 | B5: 0 | C5: =A5-D13 -> 0.062923148 | D5: =B5*C5 -> 0 | F5: =TODAY()+TIME(11,0,0) -> 46315.458 | G5: 0 | H5: =F5-I13 -> 0.062923148 | I5: =G5*H5 -> 0 | K5: =TODAY()+TIME(11,0,0) -> 46315.458 | L5: 0 | M5: =K5-N13 -> 0.062923148 | N5: =L5*M5 -> 0 | P5: =S17 | Q5: 0 | R5: =P5-L25 -> #VALUE! | S5: =R5*Q5 -> #VALUE!
A6: =TODAY()+TIME(12,0,0) -> 46315.5 | B6: 0 | C6: =A6-D13 -> 0.10458981 | D6: =B6*C6 -> 0 | F6: =TODAY()+TIME(12,0,0) -> 46315.5 | G6: 0 | H6: =F6-I13 -> 0.10458981 | I6: =G6*H6 -> 0 | K6: =TODAY()+TIME(12,0,0) -> 46315.5 | L6: 0 | M6: =K6-N13 -> 0.10458981 | N6: =L6*M6 -> 0 | P6: Total Hours Remaining | Q6: =S5 -> #VALUE! | R6: Total Pickers | S6: =Q5 -> 0
A7: =TODAY()+TIME(13,0,0) -> 46315.542 | B7: 0 | C7: =A7-D13 -> 0.14625648 | D7: =B7*C7 -> 0 | F7: =TODAY()+TIME(13,0,0) -> 46315.542 | G7: 0 | H7: =F7-I13 -> 0.14625648 | I7: =G7*H7 -> 0 | K7: =TODAY()+TIME(13,0,0) -> 46315.542 | L7: 0 | M7: =K7-N13 -> 0.14625648 | N7: =L7*M7 -> 0 | P7: Items per Picker | Q7: =Q2/(Q5) -> #DIV/0!
A8: =TODAY()+TIME(14,0,0) -> 46315.583 | B8: 0 | C8: =A8-D13 -> 0.18792315 | D8: =B8*C8 -> 0 | F8: =TODAY()+TIME(14,0,0) -> 46315.583 | G8: 0 | H8: =F8-I13 -> 0.18792315 | I8: =G8*H8 -> 0 | K8: =TODAY()+TIME(14,0,0) -> 46315.583 | L8: 0 | M8: =K8-N13 -> 0.18792315 | N8: =L8*M8 -> 0 | P8: Estimated durarion (H) | Q8: =Q2/(Q3*(Q5))/24 -> #DIV/0!
A9: =TODAY()+TIME(15,0,0) -> 46315.625 | B9: 0 | C9: =A9-D13 -> 0.22958981 | D9: =B9*C9 -> 0 | F9: =TODAY()+TIME(15,0,0) -> 46315.625 | G9: 0 | H9: =F9-I13 -> 0.22958981 | I9: =G9*H9 -> 0 | K9: =TODAY()+TIME(15,0,0) -> 46315.625 | L9: 0 | M9: =K9-N13 -> 0.22958981 | N9: =L9*M9 -> 0 | P9: Estimated Completion | Q9: =IFERROR(L25+Q8+IF(Q2>=400,TIME(0,24,0),0),"")
A10: Total Hours Remaining | B10: =D5+D6+D7+D8+D9 -> 0 | C10: Total Pickers | D10: =B9+B8+B7+B6+B5 -> 0 | F10: Total Hours Remaining | G10: =I5+I6+I7+I8+I9 -> 0 | H10: Total Pickers | I10: =G9+G8+G7+G6+G5 -> 0 | K10: Total Hours Remaining | L10: =N9+N8+N7+N6+N5 -> 0 | M10: Total Pickers | N10: =L9+L8+L7+L6+L5 -> 0
A11: Items per Picker | B11: =B2/(B6+B7+B8+B9) -> #DIV/0! | F11: Items per Picker | G11: =G2/(G6+G7+G8+G9) -> #DIV/0! | K11: Items per Picker | L11: =L2/(L6+L7+L8+L9) -> #DIV/0! | P11: PICKING VOLUME | R11: ESTIMATED COMPLETION
A12: Estimated durarion (H) | B12: =B2/(B3*(B6+B7+B8+B9+B5))/24 -> #DIV/0! | F12: Estimated durarion (H) | G12: =G2/(G3*(G6+G7+G8+G9+G5))/24 -> #DIV/0! | K12: Estimated durarion (H) | L12: =L2/(L3*(L6+L7+L8+L9+L5))/24 -> #DIV/0! | P12: MANUAL | Q12: 0 | R12: MANUAL | S12: =B13
A13: Estimated Completion | B13: =IFERROR(D13+B12+IF(B2>=3000,TIME(0,24,0),0),"") | C13: Current Time | D13: =NOW() -> 46315.395 | F13: Estimated Completion | G13: =IFERROR(I13+G12+IF(G2>=1500,TIME(0,24,0),0),"") | H13: Current Time | I13: =NOW() -> 46315.395 | K13: Estimated Completion | L13: =IFERROR(N13+L12+IF(L2>=400,TIME(0,24,0),0),"") | M13: Current Time | N13: =NOW() -> 46315.395 | P13: INSTORE | Q13: 0 | R13: INSTORE | S13: =G13
P14: FROZEN | Q14: 0 | R14: FROZEN | S14: =L13
A15: AMBIENT GTP | F15: CHILLED GTP | K15: Add hours required | L15: =N29-N28-(L17/24) -> #DIV/0! | M15: Add Hour Capacity | N15: =N16+(L16*L17) -> #DIV/0! | P15: AMBIENT GTP | Q15: 0 | R15: AMBIENT GTP | S15: =B27 | AB15: =IFERROR(((N17-N16)/L16)/24,0)+IF(AA26<0,-AA26,0) -> 0
A16: Items to pick | B16: =Q15 -> 0 | F16: Items to pick | G16: =Q16 -> 0 | K16: Picking Rate pcs/h ET | L16: =(B3*B10+G3*G10+L3*L10+B17*B24+G17*G24)/ (B10+G10+L10+B24+G24) -> #DIV/0! | M16: Picking Capacity | N16: =L16*N28*24 -> #DIV/0! | P16: CHILLED GTP | Q16: 0 | R16: CHILLED GTP | S16: =G27
A17: Picking Rate pcs/h | B17: ='Keräysteho kplh'!B5 -> 449 | F17: Picking Rate pcs/h | G17: ='Keräysteho kplh'!B6 -> 401 | K17: Add Hours | M17: Picking Volume ET | N17: =B2+G2+L2+B16+G16 -> 0 | P17: NON-FOOD INSTORE | Q17: 0 | R17: NON-FOOD INSTORE | S17: =Q9
A18: Shift End Time | B18: HC | C18: Time Remaining (H) | D18: Hours Remaining | F18: Shift End Time | G18: HC | H18: Time Remaining (H) | I18: Hours Remaining | K18: Breaks HH:MM | L18: =L26*24/1440 -> 0 | M18: Picking volume ET + KT | N18: =B2+G2+L2+Q2+B16+G16 -> 0 | P18: TOTAL | Q18: =Q12+Q13+Q14+Q15+Q16+Q17 -> 0 | R18: TOTAL | S18: =L28 -> 0
A19: =TODAY()+TIME(11,0,0) -> 46315.458 | B19: 0 | C19: =A19-D27 -> 0.062923148 | D19: =B19*C19 -> 0 | F19: =TODAY()+TIME(11,0,0) -> 46315.458 | G19: 0 | H19: =F19-I27 -> 0.062923148 | I19: =G19*H19 -> 0 | K19: Shift End Time | L19: HC ET | M19: Picking Rate pcs/h ET + KT | N19: =(B3*B10+G3*G10+L3*L10+Q3*Q6+B17*B24+G17*G24)/ (B10+G10+L10+Q6+B24+G24) -> #VALUE! | P19: Arvioitu aika | R19: Kierroksia
A20: =TODAY()+TIME(12,0,0) -> 46315.5 | B20: 0 | C20: =A20-D27 -> 0.10458981 | D20: =B20*C20 -> 0 | F20: =TODAY()+TIME(12,0,0) -> 46315.5 | G20: 0 | H20: =F20-I27 -> 0.10458981 | I20: =G20*H20 -> 0 | K20: =TODAY()+TIME(11,0,0) -> 46315.458 | L20: =G19+B19+B5+G5+L5 -> 0 | M20: =K20-L25 -> 0.062923148 | N20: =L20*M20 -> 0 | P20: TMs Left | R20: Rounds Left
A21: =TODAY()+TIME(13,0,0) -> 46315.542 | B21: 0 | C21: =A21-D27 -> 0.14625648 | D21: =B21*C21 -> 0 | F21: =TODAY()+TIME(13,0,0) -> 46315.542 | G21: 0 | H21: =F21-I27 -> 0.14625648 | I21: =G21*H21 -> 0 | K21: =TODAY()+TIME(12,0,0) -> 46315.5 | L21: =G20+B20+B6+G6+L6 -> 0 | M21: =K21-L25 -> 0.10458981 | N21: =L21*M21 -> 0 | P21: XL MANUAL | Q21: 0 | R21: ROUNDS | S21: =Q21/25 -> 0
A22: =TODAY()+TIME(14,0,0) -> 46315.583 | B22: 0 | C22: =A22-D27 -> 0.18792315 | D22: =B22*C22 -> 0 | F22: =TODAY()+TIME(14,0,0) -> 46315.583 | G22: 0 | H22: =F22-I27 -> 0.18792315 | I22: =G22*H22 -> 0 | K22: =TODAY()+TIME(13,0,0) -> 46315.542 | L22: =G21+B21+B7+G7+L7 -> 0 | M22: =K22-L25 -> 0.14625648 | N22: =L22*M22 -> 0 | P22: MANUAL | Q22: 0 | R22: ROUNDS | S22: =B32 -> 0 | T22: 47
